Workbook

Sheet Summary
A1: M06-2X/6-311++G(d) QSAR: ln k_obs vs computed descriptors
A2: k_obs measured at −2.0 V vs SHE (uncompensated potential, without iR-drop compensation). Single-descriptor least-squares fits on the bromobenzenes (n = 7); the other compounds are predicted. R² and slope (live) link to the formula cells of each chart tab. Descriptors: most favourable site; *_any uses the lowest radical-anion energy whatever its state.
A4: level | B4: rank | C4: chart tab | D4: descriptor | E4: key | F4: n | G4: R² (live) | H4: slope (live) | I4: R² | J4: slope | K4: intercept | L4: p | M4: RMSE | N4: LOO Q² | O4: pred RMSE (other groups) | P4: R² chlorobenzenes | Q4: R² halobenzenes | R4: R² all | S4: n all
A5: gas | B5: 1 | C5: gas 01 dG rad_red | D5: ΔG Ar• + e⁻ → Ar⁻ | E5: min_dG_rad_red_kcal | F5: 7 | G5: ='gas 01 dG rad_red'!Q7 | H5: ='gas 01 dG rad_red'!Q5 | I5: 0.9375 | J5: -0.1867 | K5: -10.1339 | L5: 0.0003 | M5: 0.7155 | N5: 0.8531 | O5: 2.831 | P5: 0.8079 | Q5: 0.772 | R5: 0.6864 | S5: 14
A6: gas | B6: 2 | C6: gas 02 dG RA_2e_any | D6: ΔG ArX•⁻ + e⁻ → Ar⁻ + X⁻ | E6: min_dG_RA_2e_any_kcal | F6: 7 | G6: ='gas 02 dG RA_2e_any'!Q7 | H6: ='gas 02 dG RA_2e_any'!Q5 | I6: 0.9306 | J6: -0.3432 | K6: -13.9074 | L6: 0.0004 | M6: 0.7541 | N6: 0.8854 | O6: 4.085 | P6: 0.5895 | Q6: 0.5516 | R6: 0.4478 | S6: 14
A7: gas | B7: 3 | C7: gas 03 dG frag_any | D7: ΔG ArX•⁻ → Ar• + X⁻ | E7: min_dG_frag_any_kcal | F7: 7 | G7: ='gas 03 dG frag_any'!Q7 | H7: ='gas 03 dG frag_any'!Q5 | I7: 0.9175 | J7: 0.3972 | K7: -5.5115 | L7: 0.0007 | M7: 0.822 | N7: 0.7183 | O7: 1.927 | P7: 0.8488 | Q7: 0.8357 | R7: 0.8048 | S7: 14
A8: gas | B8: 4 | C8: gas 04 dG 2e_carbanion | D8: ΔG ArX + 2e⁻ → Ar⁻ + X⁻ | E8: min_dG_2e_carbanion_kcal | F8: 7 | G8: ='gas 04 dG 2e_carbanion'!Q7 | H8: ='gas 04 dG 2e_carbanion'!Q5 | I8: 0.9152 | J8: -0.1578 | K8: -10.5053 | L8: 0.0007 | M8: 0.8333 | N8: 0.7496 | O8: 1.887 | P8: 0.8162 | Q8: 0.8748 | R8: 0.7587 | S8: 14
A9: gas | B9: 5 | C9: gas 05 dG ET_any | D9: ΔG ArX + e⁻ → ArX•⁻ | E9: dG_ET_any_kcal | F9: 7 | G9: ='gas 05 dG ET_any'!Q7 | H9: ='gas 05 dG ET_any'!Q5 | I9: 0.8662 | J9: -0.2803 | K9: -7.3735 | L9: 0.0023 | M9: 1.0469 | N9: 0.402 | O9: 2.164 | P9: 0.8538 | Q9: 0.7717 | R9: 0.7276 | S9: 14
A10: gas | B10: 6 | C10: gas 06 n_X | D10: number of halogens | E10: n_X | F10: 7 | G10: ='gas 06 n_X'!Q7 | H10: ='gas 06 n_X'!Q5 | I10: 0.8601 | J10: 1.7556 | K10: -6.915 | L10: 0.0026 | M10: 1.0705 | N10: 0.4698 | O10: 2.545 | P10: 0.7558 | Q10: 0.7082 | R10: 0.6758 | S10: 14
A11: gas | B11: 7 | C11: gas 07 wiberg_CX_parent | D11: weakest Wiberg C–X bond order | E11: min_wiberg_CX_parent | F11: 7 | G11: ='gas 07 wiberg_CX_parent'!Q7 | H11: ='gas 07 wiberg_CX_parent'!Q5 | I11: 0.8583 | J11: 327.7144 | K11: -346.2257 | L11: 0.0027 | M11: 1.0775 | N11: 0.6136 | O11: 7.137 | P11: 0.9664 | Q11: 0.2466 | R11: 0.2082 | S11: 14
A12: gas | B12: 8 | C12: gas 08 VEA | D12: vertical electron affinity | E12: VEA_eV | F12: 7 | G12: ='gas 08 VEA'!Q7 | H12: ='gas 08 VEA'!Q5 | I12: 0.8029 | J12: 4.3418 | K12: -0.4137 | L12: 0.0063 | M12: 1.2706 | N12: 0.4874 | O12: 1.806 | P12: 0.7036 | Q12: 0.7374 | R12: 0.6962 | S12: 14
A13: gas | B13: 9 | C13: gas 09 dG 2e_HDH | D13: ΔG ArX + H⁺ + 2e⁻ → ArH + X⁻ | E13: min_dG_2e_HDH_kcal | F13: 7 | G13: ='gas 09 dG 2e_HDH'!Q7 | H13: ='gas 09 dG 2e_HDH'!Q5 | I13: 0.7853 | J13: -0.7524 | K13: -321.3947 | L13: 0.0079 | M13: 1.3262 | N13: 0.0999 | O13: 5.036 | P13: 0.8894 | Q13: 0.3672 | R13: 0.3531 | S13: 14
A14: gas | B14: 10 | C14: gas 10 omega_dSCF | D14: electrophilicity index (ΔSCF) | E14: omega_dSCF_eV | F14: 7 | G14: ='gas 10 omega_dSCF'!Q7 | H14: ='gas 10 omega_dSCF'!Q5 | I14: 0.7629 | J14: 11.173 | K14: -13.6175 | L14: 0.0102 | M14: 1.3937 | N14: 0.2394 | O14: 1.577 | P14: 0.7451 | Q14: 0.7188 | R14: 0.7162 | S14: 14
A15: gas | B15: 11 | C15: gas 11 LUMO | D15: LUMO of ArX | E15: LUMO_eV | F15: 7 | G15: ='gas 11 LUMO'!Q7 | H15: ='gas 11 LUMO'!Q5 | I15: 0.7588 | J15: -5.4215 | K15: -4.9087 | L15: 0.0107 | M15: 1.4055 | N15: -0.4638 | O15: 1.623 | P15: 0.6747 | Q15: 0.7078 | R15: 0.6948 | S15: 14
A16: gas | B16: 12 | C16: gas 12 dG 1e | D16: ΔG ArX + e⁻ → Ar• + X⁻ | E16: min_dG_1e_kcal | F16: 7 | G16: ='gas 12 dG 1e'!Q7 | H16: ='gas 12 dG 1e'!Q5 | I16: 0.6766 | J16: -0.8664 | K16: -10.9226 | L16: 0.0231 | M16: 1.6276 | N16: -2.1303 | O16: 7.083 | P16: 0.8565 | Q16: 0.1941 | R16: 0.1883 | S16: 14
A17: gas | B17: 13 | C17: gas 13 BDE | D17: weakest C–X bond enthalpy | E17: min_BDE_kcal | F17: 7 | G17: ='gas 13 BDE'!Q7 | H17: ='gas 13 BDE'!Q5 | I17: 0.6389 | J17: -1.0139 | K17: 74.5381 | L17: 0.031 | M17: 1.7198 | N17: -2.0922 | O17: 14.539 | P17: 0.7111 | Q17: 0.0775 | R17: 0.0762 | S17: 14
A18: gas | B18: 14 | C18: gas 14 LUMO_RA | D18: LUMO of the radical anion ArX•⁻ | E18: LUMO_RA_eV | F18: 7 | G18: ='gas 14 LUMO_RA'!Q7 | H18: ='gas 14 LUMO_RA'!Q5 | I18: 0.4408 | J18: -5.7594 | K18: 10.3861 | L18: 0.1039 | M18: 2.1401 | N18: -0.3728 | O18: 2.65 | P18: 0.3041 | Q18: 0.3335 | R18: 0.3261 | S18: 14
A19: gas | B19: 15 | C19: gas 15 dr_CX_RA | D19: largest C–X elongation in ArX•⁻ | E19: max_dr_CX_RA_A | F19: 7 | G19: ='gas 15 dr_CX_RA'!Q7 | H19: ='gas 15 dr_CX_RA'!Q5 | I19: 0.1135 | J19: -2.4631 | K19: -0.7542 | L19: 0.4599 | M19: 2.6947 | N19: -0.9953 | O19: 2.673 | P19: 0.0048 | Q19: 0.0518 | R19: 0.027 | S19: 14
A20: gas | B20: 16 | C20: gas 16 fplus_CX | D20: largest Fukui f+ on a C–X bond | E20: max_fplus_CX | F20: 7 | G20: ='gas 16 fplus_CX'!Q7 | H20: ='gas 16 fplus_CX'!Q5 | I20: 0.0066 | J20: -2.663 | K20: -1.1421 | L20: 0.8629 | M20: 2.8526 | N20: -2.112 | O20: 2.549 | P20: 0.4767 | Q20: 0.0119 | R20: 0.0101 | S20: 14
A21: SMD | B21: 1 | C21: SMD 01 dG rad_red | D21: ΔG Ar• + e⁻ → Ar⁻ | E21: min_dG_rad_red_kcal | F21: 7 | G21: ='SMD 01 dG rad_red'!Q7 | H21: ='SMD 01 dG rad_red'!Q5 | I21: 0.8924 | J21: -0.3373 | K21: -33.757 | L21: 0.0013 | M21: 0.9389 | N21: 0.7114 | O21: 3.432 | P21: 0.817 | Q21: 0.6424 | R21: 0.6197 | S21: 14
A22: SMD | B22: 2 | C22: SMD 02 wiberg_CX_parent | D22: weakest Wiberg C–X bond order | E22: min_wiberg_CX_parent | F22: 7 | G22: ='SMD 02 wiberg_CX_parent'!Q7 | H22: ='SMD 02 wiberg_CX_parent'!Q5 | I22: 0.8822 | J22: 259.9502 | K22: -273.6079 | L22: 0.0017 | M22: 0.9824 | N22: 0.6738 | O22: 5.318 | P22: 0.9283 | Q22: 0.3934 | R22: 0.3359 | S22: 14
A23: SMD | B23: 3 | C23: SMD 03 n_X | D23: number of halogens | E23: n_X | F23: 7 | G23: ='SMD 03 n_X'!Q7 | H23: ='SMD 03 n_X'!Q5 | I23: 0.8601 | J23: 1.7556 | K23: -6.915 | L23: 0.0026 | M23: 1.0705 | N23: 0.4698 | O23: 2.545 | P23: 0.7558 | Q23: 0.7082 | R23: 0.6758 | S23: 14
A24: SMD | B24: 4 | C24: SMD 04 dG 2e_carbanion | D24: ΔG ArX + 2e⁻ → Ar⁻ + X⁻ | E24: min_dG_2e_carbanion_kcal | F24: 7 | G24: ='SMD 04 dG 2e_carbanion'!Q7 | H24: ='SMD 04 dG 2e_carbanion'!Q5 | I24: 0.8592 | J24: -0.2521 | K24: -41.0824 | L24: 0.0027 | M24: 1.074 | N24: 0.5379 | O24: 3.122 | P24: 0.8223 | Q24: 0.6139 | R24: 0.6116 | S24: 14
A25: SMD | B25: 5 | C25: SMD 05 dG0_act_concerted | D25: Savéant intrinsic barrier (weakest C–X) | E25: min_dG0_act_concerted_kcal | F25: 7 | G25: ='SMD 05 dG0_act_concerted'!Q7 | H25: ='SMD 05 dG0_act_concerted'!Q5 | I25: 0.8285 | J25: -2.5709 | K25: 65.0512 | L25: 0.0044 | M25: 1.1854 | N25: 0.1375 | O25: 9.533 | P25: 0.7702 | Q25: 0.1888 | R25: 0.1623 | S25: 14
A26: SMD | B26: 6 | C26: SMD 06 VEA | D26: vertical electron affinity | E26: VEA_eV | F26: 7 | G26: ='SMD 06 VEA'!Q7 | H26: ='SMD 06 VEA'!Q5 | I26: 0.8275 | J26: 6.8345 | K26: -11.7573 | L26: 0.0045 | M26: 1.1886 | N26: 0.2059 | O26: 1.696 | P26: 0.716 | Q26: 0.7322 | R26: 0.7183 | S26: 14
A27: SMD | B27: 7 | C27: SMD 07 dG 2e_HDH | D27: ΔG ArX + H⁺ + 2e⁻ → ArH + X⁻ | E27: min_dG_2e_HDH_kcal | F27: 7 | G27: ='SMD 07 dG 2e_HDH'!Q7 | H27: ='SMD 07 dG 2e_HDH'!Q5 | I27: 0.8172 | J27: -0.7831 | K27: -167.9041 | L27: 0.0052 | M27: 1.2238 | N27: 0.3868 | O27: 3.51 | P27: 0.8773 | Q27: 0.4663 | R27: 0.4484 | S27: 14
A28: SMD | B28: 8 | C28: SMD 08 dG act_concerted | D28: Savéant concerted barrier | E28: eff_dG_act_concerted_kcal @ -2.00 V | F28: 7 | G28: ='SMD 08 dG act_concerted'!Q7 | H28: ='SMD 08 dG act_concerted'!Q5 | I28: 0.8007 | J28: -1.0471 | K28: 20.6633 | L28: 0.0065 | M28: 1.2776 | N28: -0.0434 | O28: 2.672 | P28: 0.8484 | Q28: 0.6003 | R28: 0.5449 | S28: 14
A29: SMD | B29: 9 | C29: SMD 09 dG act_combined | D29: combined stepwise + concerted | E29: eff_dG_act_combined_kcal @ -2.00 V | F29: 7 | G29: ='SMD 09 dG act_combined'!Q7 | H29: ='SMD 09 dG act_combined'!Q5 | I29: 0.8007 | J29: -1.0471 | K29: 20.6633 | L29: 0.0065 | M29: 1.2776 | N29: -0.0434 | O29: 2.672 | P29: 0.8484 | Q29: 0.6003 | R29: 0.5449 | S29: 14
A30: SMD | B30: 10 | C30: SMD 10 omega_dSCF | D30: electrophilicity index (ΔSCF) | E30: omega_dSCF_eV | F30: 7 | G30: ='SMD 10 omega_dSCF'!Q7 | H30: ='SMD 10 omega_dSCF'!Q5 | I30: 0.7953 | J30: 8.9362 | K30: -16.6302 | L30: 0.007 | M30: 1.295 | N30: -0.1301 | O30: 1.638 | P30: 0.7414 | Q30: 0.7301 | R30: 0.7038 | S30: 14
A31: SMD | B31: 11 | C31: SMD 11 LUMO | D31: LUMO of ArX | E31: LUMO_eV | F31: 7 | G31: ='SMD 11 LUMO'!Q7 | H31: ='SMD 11 LUMO'!Q5 | I31: 0.7412 | J31: -4.8021 | K31: -3.7877 | L31: 0.0128 | M31: 1.4559 | N31: -0.6612 | O31: 1.49 | P31: 0.7307 | Q31: 0.7094 | R31: 0.7075 | S31: 14
A32: SMD | B32: 12 | C32: SMD 12 dG 1e | D32: ΔG ArX + e⁻ → Ar• + X⁻ | E32: min_dG_1e_kcal | F32: 7 | G32: ='SMD 12 dG 1e'!Q7 | H32: ='SMD 12 dG 1e'!Q5 | I32: 0.7086 | J32: -0.9294 | K32: -58.5479 | L32: 0.0175 | M32: 1.545 | N32: -0.7651 | O32: 2.993 | P32: 0.8561 | Q32: 0.4351 | R32: 0.3964 | S32: 14
A33: SMD | B33: 13 | C33: SMD 13 BDE | D33: weakest C–X bond enthalpy | E33: min_BDE_kcal | F33: 7 | G33: ='SMD 13 BDE'!Q7 | H33: ='SMD 13 BDE'!Q5 | I33: 0.7007 | J33: -1.026 | K33: 75.3209 | L33: 0.0188 | M33: 1.5658 | N33: -1.0808 | O33: 15.162 | P33: 0.7432 | Q33: 0.0822 | R33: 0.0799 | S33: 14
A34: SMD | B34: 14 | C34: SMD 14 fplus_CX | D34: largest Fukui f+ on a C–X bond | E34: max_fplus_CX | F34: 7 | G34: ='SMD 14 fplus_CX'!Q7 | H34: ='SMD 14 fplus_CX'!Q5 | I34: 0.5331 | J34: 105.2913 | K34: -15.9496 | L34: 0.0624 | M34: 1.9556 | N34: 0.1795 | O34: 5.003 | P34: 0.5645 | Q34: 0.3151 | R34: 0.2696 | S34: 14
A35: SMD | B35: 15 | C35: SMD 15 dG ET_any | D35: ΔG ArX + e⁻ → ArX•⁻ | E35: dG_ET_any_kcal | F35: 7 | G35: ='SMD 15 dG ET_any'!Q7 | H35: ='SMD 15 dG ET_any'!Q5 | I35: 0.4856 | J35: -0.2147 | K35: -14.1465 | L35: 0.0819 | M35: 2.0527 | N35: -0.9527 | O35: 1.905 | P35: 0.5258 | Q35: 0.4882 | R35: 0.4763 | S35: 14
A36: SMD | B36: 16 | C36: SMD 16 dG frag_any | D36: ΔG ArX•⁻ → Ar• + X⁻ | E36: min_dG_frag_any_kcal | F36: 7 | G36: ='SMD 16 dG frag_any'!Q7 | H36: ='SMD 16 dG frag_any'!Q5 | I36: 0.3153 | J36: 0.2104 | K36: -1.0142 | L36: 0.1897 | M36: 2.3683 | N36: -6.7526 | O36: 2.161 | P36: 0.4749 | Q36: 0.3475 | R36: 0.3357 | S36: 14
A37: SMD | B37: 17 | C37: SMD 17 dr_CX_RA | D37: largest C–X elongation in ArX•⁻ | E37: max_dr_CX_RA_A | F37: 7 | G37: ='SMD 17 dr_CX_RA'!Q7 | H37: ='SMD 17 dr_CX_RA'!Q5 | I37: 0.31 | J37: -1.5677 | K37: -0.5597 | L37: 0.1942 | M37: 2.3774 | N37: -1.063 | O37: 2.77 | P37: 0.0214 | Q37: 0.1161 | R37: 0.1116 | S37: 14
A38: SMD | B38: 18 | C38: SMD 18 dG RA_2e_any | D38: ΔG ArX•⁻ + e⁻ → Ar⁻ + X⁻ | E38: min_dG_RA_2e_any_kcal | F38: 7 | G38: ='SMD 18 dG RA_2e_any'!Q7 | H38: ='SMD 18 dG RA_2e_any'!Q5 | I38: 0.1955 | J38: -0.1704 | K38: -18.3873 | L38: 0.3205 | M38: 2.567 | N38: -1.3665 | O38: 3.789 | P38: 0.2656 | Q38: 0.0294 | R38: 0.0347 | S38: 14
A39: SMD | B39: 19 | C39: SMD 19 LUMO_RA | D39: LUMO of the radical anion ArX•⁻ | E39: LUMO_RA_eV | F39: 7 | G39: ='SMD 19 LUMO_RA'!Q7 | H39: ='SMD 19 LUMO_RA'!Q5 | I39: 0.1122 | J39: -1.8929 | K39: -3.4021 | L39: 0.4628 | M39: 2.6968 | N39: -0.7702 | O39: 1.963 | P39: 0.3594 | Q39: 0.2168 | R39: 0.2206 | S39: 14
A41: Two-descriptor models (MLR, static values)
A42: level | B42: fit set | C42: model | D42: n | E42: R² | F42: adj R² | G42: RMSE | H42: b0 | I42: b1 | J42: b2
...

Sheet Data
A1: level | B1: compound | C1: label | D1: species | E1: group | F1: kobs (1/h) | G1: SE (1/h) | H1: ln kobs | I1: LUMO_eV | J1: LUMO_RA_eV | K1: min_dG_1e_kcal | L1: min_dG_2e_carbanion_kcal | M1: dG_ET_any_kcal | N1: min_dG_frag_any_kcal | O1: min_dG_RA_2e_any_kcal | P1: n_X | Q1: VEA_eV | R1: AEA_elec_eV | S1: omega_dSCF_eV | T1: E_ET_V | U1: dG_ET_kcal | V1: min_dG_frag_kcal | W1: min_dG_RA_2e_kcal | X1: min_dG_2e_HDH_kcal | Y1: min_dG_rad_red_kcal | Z1: lambda_i_kcal | AA1: min_BDE_kcal | AB1: min_dG0_act_concerted_kcal | AC1: eff_dG_act_concerted_kcal @ -2.00 V | AD1: eff_dG_act_combined_kcal @ -2.00 V | AE1: max_fplus_CX | AF1: min_wiberg_CX_parent | AG1: max_spin_RA_X | AH1: max_dr_CX_RA_A
A2: gas | B2: Bromobenzene | C2: MonoBr | D2: BrBz_1 | E2: bromobenzene | F2: 0.002 | G2: 0.00021 | H2: -6.2146 | I2: -0.11 | J2: 2.169 | K2: -8.09 | L2: -31.81 | M2: -8.04 | N2: -0.05 | O2: -23.77 | P2: 1 | Q2: -0.76 | S2: 0.898 | X2: -420.73 | Y2: -23.72 | AA2: 77.11 | AE2: 0.0911 | AF2: 1.041 | AH2: 1.0136
A3: gas | B3: 1,4-Dibromobenzene | C3: 1,4-DiBr | D3: BrBz_14 | E3: bromobenzene | F3: 0.012 | G3: 0.0014 | H3: -4.4228 | I3: -0.299 | J3: 2.427 | K3: -8.65 | L3: -42.18 | M3: -13.4 | N3: 4.75 | O3: -28.78 | P3: 2 | Q3: -1.072 | S3: 0.791 | X3: -423.09 | Y3: -33.53 | AA3: 76.96 | AE3: 0.3699 | AF3: 1.0456 | AH3: 0.0234
A4: gas | B4: 1,3-Dibromobenzene | C4: 1,3-DiBr | D4: BrBz_13 | E4: bromobenzene | F4: 0.0329 | G4: 0.0031 | H4: -3.4143 | I4: -0.273 | J4: 2.2403 | K4: -9.35 | L4: -44.74 | M4: -14.25 | N4: 4.91 | O4: -30.49 | P4: 2 | Q4: -0.638 | S4: 0.942 | X4: -422.85 | Y4: -35.4 | AA4: 76.32 | AE4: 0.1425 | AF4: 1.0467 | AH4: 0.0336
A5: gas | B5: 1,2,4-Tribromobenzene | C5: 1,2,4-TriBr | D5: BrBz_124 | E5: bromobenzene | F5: 0.55 | G5: 0.082 | H5: -0.5978 | I5: -0.546 | J5: 2.2202 | K5: -10.52 | L5: -62.05 | M5: -21.29 | N5: 10.77 | O5: -40.76 | P5: 3 | Q5: -0.252 | S5: 1.054 | X5: -425.07 | Y5: -51.53 | AA5: 74.89 | AE5: 0.2598 | AF5: 1.0499 | AH5: 0.6785
A6: gas | B6: 1,3,5-Tribromobenzene | C6: 1,3,5-TriBr | D6: BrBz_135 | E6: bromobenzene | F6: 0.9 | G6: 0.15 | H6: -0.1054 | I6: -0.587 | J6: 2.1902 | K6: -10.28 | L6: -56.2 | M6: -20.94 | N6: 10.67 | O6: -35.26 | P6: 3 | Q6: -0.2 | S6: 1.115 | X6: -424.28 | Y6: -45.93 | AA6: 75.65 | AE6: 0.1441 | AF6: 1.0515 | AH6: 0.7074
A7: gas | B7: 1,2,4,5-Tetrabromobenzene | C7: 1,2,4,5-TetrBr | D7: BrBz_1245 | E7: bromobenzene | F7: 2.5 | G7: 0.28 | H7: 0.9163 | I7: -0.794 | J7: 2.0588 | K7: -11.14 | L7: -68.02 | M7: -25.56 | N7: 14.43 | O7: -42.46 | P7: 4 | Q7: 0.056 | S7: 1.165 | X7: -426.76 | Y7: -56.88 | AA7: 75.1 | AE7: 0.1556 | AF7: 1.0586 | AH7: 0.0172
A8: gas | B8: Hexabromobenzene | C8: HexaBr | D8: BrBz_123456 | E8: bromobenzene | F8: 10 | G8: 1.3 | H8: 2.3026 | I8: -1.601 | J8: 1.3208 | K8: -16.9 | L8: -88.01 | M8: -39.5 | N8: 22.6 | O8: -48.51 | P8: 6 | Q8: 0.876 | R8: 1.451 | S8: 1.534 | U8: -39.5 | V8: 22.6 | W8: -48.51 | X8: -432.03 | Y8: -71.11 | Z8: 27.77 | AA8: 69.97 | AE8: 0.1667 | AF8: 1.0669 | AG8: 0.08734 | AH8: 0.0665
A9: gas | B9: BDE-47 | C9: BDE-47 | D9: BDE_24_24 | E9: pbde | F9: 0.078 | G9: 0.018 | H9: -2.551 | I9: -0.723 | J9: 2.0662 | K9: -9.76 | L9: -69.77 | M9: -23.73 | N9: 13.97 | O9: -46.03 | P9: 4 | Q9: 0.042 | S9: 1.098 | X9: -424.42 | Y9: -60 | AA9: 76.05 | AE9: 0.1005 | AF9: 1.043 | AH9: 0.0103
A10: gas | B10: BDE-99 | C10: BDE-99 | D10: BDE_245_24 | E10: pbde | F10: 0.45 | G10: 0.068 | H10: -0.7985 | I10: -0.83 | J10: 1.9143 | K10: -10.15 | L10: -79.58 | M10: -24.65 | N10: 14.49 | O10: -54.93 | P10: 5 | Q10: 0.192 | R10: 0.96 | S10: 1.162 | U10: -24.65 | V10: 14.49 | W10: -54.93 | X10: -425.59 | Y10: -70.03 | Z10: 72.74 | AA10: 75.23 | AE10: 0.1321 | AF10: 1.0492 | AG10: 0.3616 | AH10: 0.7017
A11: gas | B11: Hexachlorobenzene | C11: HexaCl | D11: ClBz_123456 | E11: chlorobenzene | F11: 4.7393042 | H11: 1.5559 | I11: -0.948 | J11: 2.1696 | K11: -2.78 | L11: -73.47 | M11: -25.14 | N11: 22.36 | O11: -48.33 | P11: 6 | Q11: 0.242 | R11: 0.937 | S11: 1.288 | U11: -25.14 | V11: 22.36 | W11: -48.33 | X11: -419.86 | Y11: -70.69 | Z11: 34.38 | AA11: 91.03 | AE11: 0.2309 | AF11: 1.0898 | AG11: 0.07141 | AH11: 0.0532
A12: gas | B12: Pentachlorobenzene | C12: PentaCl | D12: ClBz_12345 | E12: chlorobenzene | F12: 0.19793594 | H12: -1.6198 | I12: -0.85 | J12: 2.1222 | K12: -1.53 | L12: -68.67 | M12: -20.78 | N12: 19.25 | O12: -47.89 | P12: 5 | Q12: 0.081 | R12: 0.762 | S12: 1.212 | U12: -20.78 | V12: 19.25 | W12: -47.89 | X12: -417.97 | Y12: -67.14 | Z12: 65.49 | AA12: 91.2 | AE12: 0.2358 | AF12: 1.08 | AG12: 0.36801 | AH12: 0.5429
A13: gas | B13: 1,2,4,5-Tetrachlorobenzene | C13: 1,2,4,5-TetraCl | D13: ClBz_1245 | E13: chlorobenzene | F13: 0.29523017 | H13: -1.22 | I13: -0.745 | J13: 3.0294 | K13: -0.27 | L13: -54.94 | M13: -9.35 | N13: 9.08 | O13: -45.58 | P13: 4 | Q13: -0.09 | R13: 0.21 | S13: 1.135 | U13: -9.35 | V13: 9.08 | W13: -45.58 | X13: -416.53 | Y13: -54.67 | Z13: 19.45 | AA13: 93.13 | AE13: 0.1501 | AF13: 1.0771 | AG13: 0.04014 | AH13: 0.0483
A14: gas | B14: 1,2-Dichlorobenzene | C14: 1,2-DiCl | D14: ClBz_12 | E14: chlorobenzene | F14: 0.042852127 | H14: -3.15 | I14: -0.158 | J14: 2.233 | K14: 0.5 | L14: -39.66 | M14: -4.66 | N14: 5.15 | O14: -35.01 | P14: 2 | Q14: -0.791 | S14: 0.905 | X14: -414.55 | Y14: -40.16 | AA14: 93.47 | AE14: 0.1588 | AF14: 1.0691 | AH14: 0.7839
A15: gas | B15: 1,4-Dichlorobenzene | C15: 1,4-DiCl | D15: ClBz_14 | E15: chlorobenzene | F15: 0.000905247 | H15: -7.0073 | I15: -0.236 | J15: 3.0384 | K15: 1.52 | L15: -30.91 | M15: 6.5 | N15: -4.97 | O15: -37.41 | P15: 2 | Q15: -0.72 | R15: -0.492 | S15: 0.911 | U15: 6.5 | V15: -4.97 | W15: -37.41 | X15: -413.02 | Y15: -32.43 | Z15: 13.3 | AA15: 94.37 | AE15: 0.1423 | AF15: 1.0586 | AG15: 0.02006 | AH15: 0.0516
A16: SMD | B16: Bromobenzene | C16: MonoBr | D16: BrBz_1 | E16: bromobenzene | F16: 0.002 | G16: 0.00021 | H16: -6.2146 | I16: 0.108 | J16: -1.3622 | K16: -58.53 | L16: -143.45 | M16: -57.07 | N16: -1.45 | O16: -86.37 | P16: 1 | Q16: 0.995 | S16: 1.339 | X16: -208.14 | Y16: -84.92 | AA16: 77.27 | AB16: 27.21 | AC16: 24.32 | AD16: 24.32 | AE16: 0.1078 | AF16: 1.0326 | AH16: 2.9934
A17: SMD | B17: 1,4-Dibromobenzene | C17: 1,4-DiBr | D17: BrBz_14 | E17: bromobenzene | F17: 0.012 | G17: 0.0014 | H17: -4.4228 | I17: -0.129 | J17: 0.0947 | K17: -59.17 | L17: -147.54 | M17: -38.03 | N17: -21.14 | O17: -109.51 | P17: 2 | Q17: 1.228 | R17: 1.454 | S17: 1.48 | T17: -2.632 | U17: -38.03 | V17: -21.14 | W17: -109.51 | X17: -210.15 | Y17: -88.37 | Z17: 13.75 | AA17: 77.02 | AB17: 26.73 | AC17: 23.12932 | AD17: 23.12932 | AE17: 0.1148 | AF17: 1.0385 | AG17: 0.03368 | AH17: 0.0447
A18: SMD | B18: 1,3-Dibromobenzene | C18: 1,3-DiBr | D18: BrBz_13 | E18: bromobenzene | F18: 0.0329 | G18: 0.0031 | H18: -3.4143 | I18: -0.101 | J18: -0.9763 | K18: -60.07 | L18: -149.49 | M18: -57.88 | N18: -2.19 | O18: -91.61 | P18: 2 | Q18: 1.243 | S18: 1.503 | X18: -210.21 | Y18: -89.42 | AA18: 76.25 | AB18: 26.53 | AC18: 22.51932 | AD18: 22.51932 | AE18: 0.1492 | AF18: 1.0397 | AH18: 0.0053
A19: SMD | B19: 1,2,4-Tribromobenzene | C19: 1,2,4-TriBr | D19: BrBz_124 | E19: bromobenzene | F19: 0.55 | G19: 0.082 | H19: -0.5978 | I19: -0.355 | J19: -0.8757 | K19: -61.34 | L19: -159.44 | M19: -60.65 | N19: -0.69 | O19: -98.79 | P19: 3 | Q19: 1.456 | S19: 1.641 | X19: -212.51 | Y19: -98.1 | AA19: 74.67 | AB19: 25.79 | AC19: 21.28974 | AD19: 21.28974 | AE19: 0.1495 | AF19: 1.0447 | AH19: 0.7661
A20: SMD | B20: 1,3,5-Tribromobenzene | C20: 1,3,5-TriBr | D20: BrBz_135 | E20: bromobenzene | F20: 0.9 | G20: 0.15 | H20: -0.1054 | I20: -0.424 | J20: -0.7437 | K20: -60.43 | L20: -154.81 | M20: -59.76 | N20: -0.67 | O20: -95.04 | P20: 3 | Q20: 1.477 | S20: 1.678 | X20: -211.53 | Y20: -94.37 | AA20: 75.39 | AB20: 25.98 | AC20: 21.55909 | AD20: 21.55909 | AE20: 0.122 | AF20: 1.047 | AH20: 1.0271
A21: SMD | B21: 1,2,4,5-Tetrabromobenzene | C21: 1,2,4,5-TetrBr | D21: BrBz_1245 | E21: bromobenzene | F21: 2.5 | G21: 0.28 | H21: 0.9163 | I21: -0.646 | J21: -0.975 | K21: -62.05 | L21: -163.23 | M21: -63.06 | N21: 1.02 | O21: -100.17 | P21: 4 | Q21: 1.69 | S21: 1.811 | X21: -214.59 | Y21: -101.19 | AA21: 74.73 | AB21: 25.53 | AC21: 20.19864 | AD21: 20.19864 | AE21: 0.1409 | AF21: 1.0553 | AH21: 0.0088
A22: SMD | B22: Hexabromobenzene | C22: HexaBr | D22: BrBz_123456 | E22: bromobenzene | F22: 10 | G22: 1.3 | H22: 2.3026 | I22: -1.572 | J22: -1.6485 | K22: -66.96 | L22: -176.96 | M22: -70.99 | N22: 4.03 | O22: -105.97 | P22: 6 | Q22: 2.265 | R22: 2.941 | S22: 2.284 | T22: -1.203 | U22: -70.99 | V22: 4.03 | W22: -105.97 | X22: -218.95 | Y22: -110 | Z22: 56.46 | AA22: 69.8 | AB22: 23.84 | AC22: 16.13841 | AD22: 16.13841 | AE22: 0.1666 | AF22: 1.0656 | AG22: 0.01853 | AH22: 0.0138
A23: SMD | B23: BDE-47 | C23: BDE-47 | D23: BDE_24_24 | E23: pbde | F23: 0.078 | G23: 0.018 | H23: -2.551 | I23: -0.454 | J23: -0.8188 | K23: -60.93 | L23: -162.15 | M23: -58.98 | N23: -1.95 | O23: -103.17 | P23: 4 | Q23: 1.353 | S23: 1.537 | X23: -212.25 | Y23: -101.22 | AA23: 75.47 | AB23: 24.82 | AC23: 20.29653 | AD23: 20.29653 | AE23: 0.1289 | AF23: 1.0374 | AH23: 1.1574
A24: SMD | B24: BDE-99 | C24: BDE-99 | D24: BDE_245_24 | E24: pbde | F24: 0.45 | G24: 0.068 | H24: -0.7985 | I24: -0.613 | J24: -1.0289 | K24: -60.71 | L24: -168.45 | M24: -58.32 | N24: -2.39 | O24: -110.13 | P24: 5 | Q24: 1.48 | R24: 2.452 | S24: 1.636 | T24: -1.752 | U24: -58.32 | V24: -2.39 | W24: -110.13 | X24: -212.98 | Y24: -108.56 | AA24: 74.88 | AB24: 24.54 | AC24: 20.17854 | AD24: 20.17854 | AE24: 0.1132 | AF24: 1.0422 | AH24: 0.7541
A25: SMD | B25: Hexachlorobenzene | C25: HexaCl | D25: ClBz_123456 | E25: chlorobenzene | F25: 4.7393042 | H25: 1.5559 | I25: -0.78 | J25: -1.0397 | K25: -65.64 | L25: -180.17 | M25: -63.14 | N25: -2.5 | O25: -117.03 | P25: 6 | Q25: 1.901 | R25: 2.538 | S25: 1.982 | T25: -1.543 | U25: -63.14 | V25: -2.5 | W25: -117.03 | X25: -220 | Y25: -114.54 | Z25: 32.79 | AA25: 91.35 | AB25: 29.54 | AC25: 22.32841 | AD25: 22.32841 | AE25: 0.2347 | AF25: 1.0858 | AG25: 0.07075 | AH25: 0.0492
A26: SMD | B26: Pentachlorobenzene | C26: PentaCl | D26: ClBz_12345 | E26: chlorobenzene | F26: 0.19793594 | H26: -1.6198 | I26: -0.622 | J26: -1.5758 | K26: -65.01 | L26: -177.44 | M26: -65.34 | N26: 0.33 | O26: -112.1 | P26: 5 | Q26: 1.782 | R26: 2.698 | S26: 1.881 | T26: -1.448 | U26: -65.34 | V26: 0.33 | W26: -112.1 | X26: -218.52 | Y26: -112.43 | Z26: 81.84 | AA26: 91.57 | AB26: 29.79 | AC26: 23.30434 | AD26: 23.30434 | AE26: 0.2327 | AF26: 1.0752 | AG26: 0.3096 | AH26: 0.7349
A27: SMD | B27: 1,2,4,5-Tetrachlorobenzene | C27: 1,2,4,5-TetraCl | D27: ClBz_1245 | E27: chlorobenzene | F27: 0.29523017 | H27: -1.22 | I27: -0.47 | J27: -0.0639 | K27: -63.8 | L27: -166.28 | M27: -48.54 | N27: -15.26 | O27: -117.74 | P27: 4 | Q27: 1.664 | R27: 1.905 | S27: 1.783 | T27: -2.176 | U27: -48.54 | V27: -15.26 | W27: -117.74 | X27: -217.06 | Y27: -102.48 | Z27: 15.49 | AA27: 93.41 | AB27: 30.47 | AC27: 24.30864 | AD27: 24.30864 | AE27: 0.1362 | AF27: 1.07 | AG27: 0.02793 | AH27: 0.0312
A28: SMD | B28: 1,2-Dichlorobenzene | C28: 1,2-DiCl | D28: ClBz_12 | E28: chlorobenzene | F28: 0.042852127 | H28: -3.15 | I28: 0.019 | J28: 0.1793 | K28: -62.83 | L28: -158.44 | M28: -37.86 | N28: -24.97 | O28: -120.58 | P28: 2 | Q28: 1.21 | R28: 1.409 | S28: 1.474 | T28: -2.639 | U28: -37.86 | V28: -24.97 | W28: -120.58 | X28: -214.38 | Y28: -95.61 | Z28: 10.23 | AA28: 93.98 | AB28: 31.15 | AC28: 25.83932 | AD28: 25.83932 | AE28: 0.1304 | AF28: 1.0577 | AG28: 0.01308 | AH28: 0.0196
A29: SMD | B29: 1,4-Dichlorobenzene | C29: 1,4-DiCl | D29: ClBz_14 | E29: chlorobenzene | F29: 0.000905247 | H29: -7.0073 | I29: -0.014 | J29: 0.1467 | K29: -61.79 | L29: -150.05 | M29: -40.22 | N29: -21.57 | O29: -109.84 | P29: 2 | Q29: 1.249 | R29: 1.449 | S29: 1.486 | T29: -2.537 | U29: -40.22 | V29: -21.57 | W29: -109.84 | X29: -212.81 | Y29: -88.27 | Z29: 9.4 | AA29: 94.9 | AB29: 31.38 | AC29: 26.53932 | AD29: 26.53932 | AE29: 0.1123 | AF29: 1.0475 | AG29: 0.00616 | AH29: 0.0252

Sheet gas 01 dG rad_red
A1: min_dG_rad_red_kcal | B1: published bromobenzene data | C1: label | D1: y error | G1: min_dG_rad_red_kcal | H1: new chlorobenzene data | I1: label | K1: min_dG_rad_red_kcal | L1: published PBDE data | M1: label | N1: y error | P1: fit x | Q1: fit: published bromobenzene data
A2: -23.72 | B2: -6.2146 | C2: MonoBr | D2: 0.105 | G2: -70.69 | H2: 1.5559 | I2: HexaCl | K2: -60 | L2: -2.551 | M2: BDE-47 | N2: 0.2308 | P2: =MIN($A$2:$A$8) | Q2: =$Q$6+$Q$5*P2
A3: -33.53 | B3: -4.4228 | C3: 1,4-DiBr | D3: 0.1167 | G3: -67.14 | H3: -1.6198 | I3: PentaCl | K3: -70.03 | L3: -0.7985 | M3: BDE-99 | N3: 0.1511 | P3: =MAX($A$2:$A$8) | Q3: =$Q$6+$Q$5*P3
A4: -35.4 | B4: -3.4143 | C4: 1,3-DiBr | D4: 0.0942 | G4: -54.67 | H4: -1.22 | I4: 1,2,4,5-TetraCl
A5: -51.53 | B5: -0.5978 | C5: 1,2,4-TriBr | D5: 0.1491 | G5: -40.16 | H5: -3.15 | I5: 1,2-DiCl | P5: slope | Q5: =SLOPE($B$2:$B$8,$A$2:$A$8)
A6: -45.93 | B6: -0.1054 | C6: 1,3,5-TriBr | D6: 0.1667 | G6: -32.43 | H6: -7.0073 | I6: 1,4-DiCl | P6: intercept | Q6: =INTERCEPT($B$2:$B$8,$A$2:$A$8)
A7: -56.88 | B7: 0.9163 | C7: 1,2,4,5-TetrBr | D7: 0.112 | P7: R2 | Q7: =RSQ($B$2:$B$8,$A$2:$A$8)
A8: -71.11 | B8: 2.3026 | C8: HexaBr | D8: 0.13
S17: Natural logarithm of the observed pseudo-first-order rate constants (k_obs, h⁻¹) for electrochemical dehalogenation at −2.0 V vs SHE (uncompensated potential, without iR-drop compensation) [add electrode, cell, electrolyte and pH], plotted against descriptors computed at M06-2X/6-311++G(d), gas phase. Filled gray circles are published bromobenzene data, open circles are new chlorobenzene data and gray squares are published PBDE data. Error bars are ±1 standard error of k_obs propagated to ln k_obs (no standard errors are available for the chlorobenzenes). The dotted line is the least-squares fit to the bromobenzenes (R² = 0.94, n = 7). The other compounds are predicted by that fit. Compounds are labelled by shorthand. Fit line, slope, intercept and R² are Excel formulas (SLOPE, INTERCEPT, RSQ) over the bromobenzene cells beside the chart.

Sheet gas 02 dG RA_2e_any
A1: min_dG_RA_2e_any_kcal | B1: published bromobenzene data | C1: label | D1: y error | G1: min_dG_RA_2e_any_kcal | H1: new chlorobenzene data | I1: label | K1: min_dG_RA_2e_any_kcal | L1: published PBDE data | M1: label | N1: y error | P1: fit x | Q1: fit: published bromobenzene data
A2: -23.77 | B2: -6.2146 | C2: MonoBr | D2: 0.105 | G2: -48.33 | H2: 1.5559 | I2: HexaCl | K2: -46.03 | L2: -2.551 | M2: BDE-47 | N2: 0.2308 | P2: =MIN($A$2:$A$8) | Q2: =$Q$6+$Q$5*P2
A3: -28.78 | B3: -4.4228 | C3: 1,4-DiBr | D3: 0.1167 | G3: -47.89 | H3: -1.6198 | I3: PentaCl | K3: -54.93 | L3: -0.7985 | M3: BDE-99 | N3: 0.1511 | P3: =MAX($A$2:$A$8) | Q3: =$Q$6+$Q$5*P3
A4: -30.49 | B4: -3.4143 | C4: 1,3-DiBr | D4: 0.0942 | G4: -45.58 | H4: -1.22 | I4: 1,2,4,5-TetraCl
A5: -40.76 | B5: -0.5978 | C5: 1,2,4-TriBr | D5: 0.1491 | G5: -35.01 | H5: -3.15 | I5: 1,2-DiCl | P5: slope | Q5: =SLOPE($B$2:$B$8,$A$2:$A$8)
A6: -35.26 | B6: -0.1054 | C6: 1,3,5-TriBr | D6: 0.1667 | G6: -37.41 | H6: -7.0073 | I6: 1,4-DiCl | P6: intercept | Q6: =INTERCEPT($B$2:$B$8,$A$2:$A$8)
A7: -42.46 | B7: 0.9163 | C7: 1,2,4,5-TetrBr | D7: 0.112 | P7: R2 | Q7: =RSQ($B$2:$B$8,$A$2:$A$8)
A8: -48.51 | B8: 2.3026 | C8: HexaBr | D8: 0.13
S17: Natural logarithm of the observed pseudo-first-order rate constants (k_obs, h⁻¹) for electrochemical dehalogenation at −2.0 V vs SHE [add electrode, cell, electrolyte and pH], plotted against descriptors computed at M06-2X/6-311++G(d), gas phase. Filled gray circles are published bromobenzene data, open circles are new chlorobenzene data and gray squares are published PBDE data. Error bars are ±1 standard error of k_obs propagated to ln k_obs (no standard errors are available for the chlorobenzenes). The dotted line is the least-squares fit to the bromobenzenes (R² = 0.93, n = 7). The other compounds are predicted by that fit. Compounds are labelled by shorthand. Fit line, slope, intercept and R² are Excel formulas (SLOPE, INTERCEPT, RSQ) over the bromobenzene cells beside the chart.

Sheet gas 03 dG frag_any
A1: min_dG_frag_any_kcal | B1: published bromobenzene data | C1: label | D1: y error | G1: min_dG_frag_any_kcal | H1: new chlorobenzene data | I1: label | K1: min_dG_frag_any_kcal | L1: published PBDE data | M1: label | N1: y error | P1: fit x | Q1: fit: published bromobenzene data
A2: -0.05 | B2: -6.2146 | C2: MonoBr | D2: 0.105 | G2: 22.36 | H2: 1.5559 | I2: HexaCl | K2: 13.97 | L2: -2.551 | M2: BDE-47 | N2: 0.2308 | P2: =MIN($A$2:$A$8) | Q2: =$Q$6+$Q$5*P2
A3: 4.75 | B3: -4.4228 | C3: 1,4-DiBr | D3: 0.1167 | G3: 19.25 | H3: -1.6198 | I3: PentaCl | K3: 14.49 | L3: -0.7985 | M3: BDE-99 | N3: 0.1511 | P3: =MAX($A$2:$A$8) | Q3: =$Q$6+$Q$5*P3
A4: 4.91 | B4: -3.4143 | C4: 1,3-DiBr | D4: 0.0942 | G4: 9.08 | H4: -1.22 | I4: 1,2,4,5-TetraCl
A5: 10.77 | B5: -0.5978 | C5: 1,2,4-TriBr | D5: 0.1491 | G5: 5.15 | H5: -3.15 | I5: 1,2-DiCl | P5: slope | Q5: =SLOPE($B$2:$B$8,$A$2:$A$8)
A6: 10.67 | B6: -0.1054 | C6: 1,3,5-TriBr | D6: 0.1667 | G6: -4.97 | H6: -7.0073 | I6: 1,4-DiCl | P6: intercept | Q6: =INTERCEPT($B$2:$B$8,$A$2:$A$8)
A7: 14.43 | B7: 0.9163 | C7: 1,2,4,5-TetrBr | D7: 0.112 | P7: R2 | Q7: =RSQ($B$2:$B$8,$A$2:$A$8)
A8: 22.6 | B8: 2.3026 | C8: HexaBr | D8: 0.13
S17: Natural logarithm of the observed pseudo-first-order rate constants (k_obs, h⁻¹) for electrochemical dehalogenation at −2.0 V vs SHE [add electrode, cell, electrolyte and pH], plotted against descriptors computed at M06-2X/6-311++G(d), gas phase. Filled gray circles are published bromobenzene data, open circles are new chlorobenzene data and gray squares are published PBDE data. Error bars are ±1 standard error of k_obs propagated to ln k_obs (no standard errors are available for the chlorobenzenes). The dotted line is the least-squares fit to the bromobenzenes (R² = 0.92, n = 7). The other compounds are predicted by that fit. Compounds are labelled by shorthand. Fit line, slope, intercept and R² are Excel formulas (SLOPE, INTERCEPT, RSQ) over the bromobenzene cells beside the chart.

Sheet gas 04 dG 2e_carbanion
A1: min_dG_2e_carbanion_kcal | B1: published bromobenzene data | C1: label | D1: y error | G1: min_dG_2e_carbanion_kcal | H1: new chlorobenzene data | I1: label | K1: min_dG_2e_carbanion_kcal | L1: published PBDE data | M1: label | N1: y error | P1: fit x | Q1: fit: published bromobenzene data
A2: -31.81 | B2: -6.2146 | C2: MonoBr | D2: 0.105 | G2: -73.47 | H2: 1.5559 | I2: HexaCl | K2: -69.77 | L2: -2.551 | M2: BDE-47 | N2: 0.2308 | P2: =MIN($A$2:$A$8) | Q2: =$Q$6+$Q$5*P2
A3: -42.18 | B3: -4.4228 | C3: 1,4-DiBr | D3: 0.1167 | G3: -68.67 | H3: -1.6198 | I3: PentaCl | K3: -79.58 | L3: -0.7985 | M3: BDE-99 | N3: 0.1511 | P3: =MAX($A$2:$A$8) | Q3: =$Q$6+$Q$5*P3
A4: -44.74 | B4: -3.4143 | C4: 1,3-DiBr | D4: 0.0942 | G4: -54.94 | H4: -1.22 | I4: 1,2,4,5-TetraCl
A5: -62.05 | B5: -0.5978 | C5: 1,2,4-TriBr | D5: 0.1491 | G5: -39.66 | H5: -3.15 | I5: 1,2-DiCl | P5: slope | Q5: =SLOPE($B$2:$B$8,$A$2:$A$8)
A6: -56.2 | B6: -0.1054 | C6: 1,3,5-TriBr | D6: 0.1667 | G6: -30.91 | H6: -7.0073 | I6: 1,4-DiCl | P6: intercept | Q6: =INTERCEPT($B$2:$B$8,$A$2:$A$8)
A7: -68.02 | B7: 0.9163 | C7: 1,2,4,5-TetrBr | D7: 0.112 | P7: R2 | Q7: =RSQ($B$2:$B$8,$A$2:$A$8)
A8: -88.01 | B8: 2.3026 | C8: HexaBr | D8: 0.13
S17: Natural logarithm of the observed pseudo-first-order rate constants (k_obs, h⁻¹) for electrochemical dehalogenation at −2.0 V vs SHE [add electrode, cell, electrolyte and pH], plotted against descriptors computed at M06-2X/6-311++G(d), gas phase. Filled gray circles are published bromobenzene data, open circles are new chlorobenzene data and gray squares are published PBDE data. Error bars are ±1 standard error of k_obs propagated to ln k_obs (no standard errors are available for the chlorobenzenes). The dotted line is the least-squares fit to the bromobenzenes (R² = 0.92, n = 7). The other compounds are predicted by that fit. Compounds are labelled by shorthand. Fit line, slope, intercept and R² are Excel formulas (SLOPE, INTERCEPT, RSQ) over the bromobenzene cells beside the chart.

Sheet gas 05 dG ET_any
A1: dG_ET_any_kcal | B1: published bromobenzene data | C1: label | D1: y error | G1: dG_ET_any_kcal | H1: new chlorobenzene data | I1: label | K1: dG_ET_any_kcal | L1: published PBDE data | M1: label | N1: y error | P1: fit x | Q1: fit: published bromobenzene data
A2: -8.04 | B2: -6.2146 | C2: MonoBr | D2: 0.105 | G2: -25.14 | H2: 1.5559 | I2: HexaCl | K2: -23.73 | L2: -2.551 | M2: BDE-47 | N2: 0.2308 | P2: =MIN($A$2:$A$8) | Q2: =$Q$6+$Q$5*P2
A3: -13.4 | B3: -4.4228 | C3: 1,4-DiBr | D3: 0.1167 | G3: -20.78 | H3: -1.6198 | I3: PentaCl | K3: -24.65 | L3: -0.7985 | M3: BDE-99 | N3: 0.1511 | P3: =MAX($A$2:$A$8) | Q3: =$Q$6+$Q$5*P3
A4: -14.25 | B4: -3.4143 | C4: 1,3-DiBr | D4: 0.0942 | G4: -9.35 | H4: -1.22 | I4: 1,2,4,5-TetraCl
A5: -21.29 | B5: -0.5978 | C5: 1,2,4-TriBr | D5: 0.1491 | G5: -4.66 | H5: -3.15 | I5: 1,2-DiCl | P5: slope | Q5: =SLOPE($B$2:$B$8,$A$2:$A$8)
A6: -20.94 | B6: -0.1054 | C6: 1,3,5-TriBr | D6: 0.1667 | G6: 6.5 | H6: -7.0073 | I6: 1,4-DiCl | P6: intercept | Q6: =INTERCEPT($B$2:$B$8,$A$2:$A$8)
A7: -25.56 | B7: 0.9163 | C7: 1,2,4,5-TetrBr | D7: 0.112 | P7: R2 | Q7: =RSQ($B$2:$B$8,$A$2:$A$8)
A8: -39.5 | B8: 2.3026 | C8: HexaBr | D8: 0.13
S17: Natural logarithm of the observed pseudo-first-order rate constants (k_obs, h⁻¹) for electrochemical dehalogenation at −2.0 V vs SHE [add electrode, cell, electrolyte and pH], plotted against descriptors computed at M06-2X/6-311++G(d), gas phase. Filled gray circles are published bromobenzene data, open circles are new chlorobenzene data and gray squares are published PBDE data. Error bars are ±1 standard error of k_obs propagated to ln k_obs (no standard errors are available for the chlorobenzenes). The dotted line is the least-squares fit to the bromobenzenes (R² = 0.87, n = 7). The other compounds are predicted by that fit. Compounds are labelled by shorthand. Fit line, slope, intercept and R² are Excel formulas (SLOPE, INTERCEPT, RSQ) over the bromobenzene cells beside the chart.

Sheet gas 06 n_X
A1: n_X | B1: published bromobenzene data | C1: label | D1: y error | G1: n_X | H1: new chlorobenzene data | I1: label | K1: n_X | L1: published PBDE data | M1: label | N1: y error | P1: fit x | Q1: fit: published bromobenzene data
A2: 1 | B2: -6.2146 | C2: MonoBr | D2: 0.105 | G2: 6 | H2: 1.5559 | I2: HexaCl | K2: 4 | L2: -2.551 | M2: BDE-47 | N2: 0.2308 | P2: =MIN($A$2:$A$8) | Q2: =$Q$6+$Q$5*P2
A3: 2 | B3: -4.4228 | C3: 1,4-DiBr | D3: 0.1167 | G3: 5 | H3: -1.6198 | I3: PentaCl | K3: 5 | L3: -0.7985 | M3: BDE-99 | N3: 0.1511 | P3: =MAX($A$2:$A$8) | Q3: =$Q$6+$Q$5*P3
A4: 2 | B4: -3.4143 | C4: 1,3-DiBr | D4: 0.0942 | G4: 4 | H4: -1.22 | I4: 1,2,4,5-TetraCl
A5: 3 | B5: -0.5978 | C5: 1,2,4-TriBr | D5: 0.1491 | G5: 2 | H5: -3.15 | I5: 1,2-DiCl | P5: slope | Q5: =SLOPE($B$2:$B$8,$A$2:$A$8)
A6: 3 | B6: -0.1054 | C6: 1,3,5-TriBr | D6: 0.1667 | G6: 2 | H6: -7.0073 | I6: 1,4-DiCl | P6: intercept | Q6: =INTERCEPT($B$2:$B$8,$A$2:$A$8)
A7: 4 | B7: 0.9163 | C7: 1,2,4,5-TetrBr | D7: 0.112 | P7: R2 | Q7: =RSQ($B$2:$B$8,$A$2:$A$8)
A8: 6 | B8: 2.3026 | C8: HexaBr | D8: 0.13
S17: Natural logarithm of the observed pseudo-first-order rate constants (k_obs, h⁻¹) for electrochemical dehalogenation at −2.0 V vs SHE [add electrode, cell, electrolyte and pH], plotted against descriptors computed at M06-2X/6-311++G(d), gas phase. Filled gray circles are published bromobenzene data, open circles are new chlorobenzene data and gray squares are published PBDE data. Error bars are ±1 standard error of k_obs propagated to ln k_obs (no standard errors are available for the chlorobenzenes). The dotted line is the least-squares fit to the bromobenzenes (R² = 0.86, n = 7). The other compounds are predicted by that fit. Compounds are labelled by shorthand. Fit line, slope, intercept and R² are Excel formulas (SLOPE, INTERCEPT, RSQ) over the bromobenzene cells beside the chart.

Sheet gas 07 wiberg_CX_parent
A1: min_wiberg_CX_parent | B1: published bromobenzene data | C1: label | D1: y error | G1: min_wiberg_CX_parent | H1: new chlorobenzene data | I1: label | K1: min_wiberg_CX_parent | L1: published PBDE data | M1: label | N1: y error | P1: fit x | Q1: fit: published bromobenzene data
A2: 1.041 | B2: -6.2146 | C2: MonoBr | D2: 0.105 | G2: 1.0898 | H2: 1.5559 | I2: HexaCl | K2: 1.043 | L2: -2.551 | M2: BDE-47 | N2: 0.2308 | P2: =MIN($A$2:$A$8) | Q2: =$Q$6+$Q$5*P2
A3: 1.0456 | B3: -4.4228 | C3: 1,4-DiBr | D3: 0.1167 | G3: 1.08 | H3: -1.6198 | I3: PentaCl | K3: 1.0492 | L3: -0.7985 | M3: BDE-99 | N3: 0.1511 | P3: =MAX($A$2:$A$8) | Q3: =$Q$6+$Q$5*P3
A4: 1.0467 | B4: -3.4143 | C4: 1,3-DiBr | D4: 0.0942 | G4: 1.0771 | H4: -1.22 | I4: 1,2,4,5-TetraCl
A5: 1.0499 | B5: -0.5978 | C5: 1,2,4-TriBr | D5: 0.1491 | G5: 1.0691 | H5: -3.15 | I5: 1,2-DiCl | P5: slope | Q5: =SLOPE($B$2:$B$8,$A$2:$A$8)
A6: 1.0515 | B6: -0.1054 | C6: 1,3,5-TriBr | D6: 0.1667 | G6: 1.0586 | H6: -7.0073 | I6: 1,4-DiCl | P6: intercept | Q6: =INTERCEPT($B$2:$B$8,$A$2:$A$8)
A7: 1.0586 | B7: 0.9163 | C7: 1,2,4,5-TetrBr | D7: 0.112 | P7: R2 | Q7: =RSQ($B$2:$B$8,$A$2:$A$8)
A8: 1.0669 | B8: 2.3026 | C8: HexaBr | D8: 0.13
S17: Natural logarithm of the observed pseudo-first-order rate constants (k_obs, h⁻¹) for electrochemical dehalogenation at −2.0 V vs SHE [add electrode, cell, electrolyte and pH], plotted against descriptors computed at M06-2X/6-311++G(d), gas phase. Filled gray circles are published bromobenzene data, open circles are new chlorobenzene data and gray squares are published PBDE data. Error bars are ±1 standard error of k_obs propagated to ln k_obs (no standard errors are available for the chlorobenzenes). The dotted line is the least-squares fit to the bromobenzenes (R² = 0.86, n = 7). The other compounds are predicted by that fit. Compounds are labelled by shorthand. Fit line, slope, intercept and R² are Excel formulas (SLOPE, INTERCEPT, RSQ) over the bromobenzene cells beside the chart.

Sheet gas 08 VEA
A1: VEA_eV | B1: published bromobenzene data | C1: label | D1: y error | G1: VEA_eV | H1: new chlorobenzene data | I1: label | K1: VEA_eV | L1: published PBDE data | M1: label | N1: y error | P1: fit x | Q1: fit: published bromobenzene data
A2: -0.76 | B2: -6.2146 | C2: MonoBr | D2: 0.105 | G2: 0.242 | H2: 1.5559 | I2: HexaCl | K2: 0.042 | L2: -2.551 | M2: BDE-47 | N2: 0.2308 | P2: =MIN($A$2:$A$8) | Q2: =$Q$6+$Q$5*P2
A3: -1.072 | B3: -4.4228 | C3: 1,4-DiBr | D3: 0.1167 | G3: 0.081 | H3: -1.6198 | I3: PentaCl | K3: 0.192 | L3: -0.7985 | M3: BDE-99 | N3: 0.1511 | P3: =MAX($A$2:$A$8) | Q3: =$Q$6+$Q$5*P3
A4: -0.638 | B4: -3.4143 | C4: 1,3-DiBr | D4: 0.0942 | G4: -0.09 | H4: -1.22 | I4: 1,2,4,5-TetraCl
A5: -0.252 | B5: -0.5978 | C5: 1,2,4-TriBr | D5: 0.1491 | G5: -0.791 | H5: -3.15 | I5: 1,2-DiCl | P5: slope | Q5: =SLOPE($B$2:$B$8,$A$2:$A$8)
A6: -0.2 | B6: -0.1054 | C6: 1,3,5-TriBr | D6: 0.1667 | G6: -0.72 | H6: -7.0073 | I6: 1,4-DiCl | P6: intercept | Q6: =INTERCEPT($B$2:$B$8,$A$2:$A$8)
A7: 0.056 | B7: 0.9163 | C7: 1,2,4,5-TetrBr | D7: 0.112 | P7: R2 | Q7: =RSQ($B$2:$B$8,$A$2:$A$8)
A8: 0.876 | B8: 2.3026 | C8: HexaBr | D8: 0.13
S17: Natural logarithm of the observed pseudo-first-order rate constants (k_obs, h⁻¹) for electrochemical dehalogenation at −2.0 V vs SHE [add electrode, cell, electrolyte and pH], plotted against descriptors computed at M06-2X/6-311++G(d), gas phase. Filled gray circles are published bromobenzene data, open circles are new chlorobenzene data and gray squares are published PBDE data. Error bars are ±1 standard error of k_obs propagated to ln k_obs (no standard errors are available for the chlorobenzenes). The dotted line is the least-squares fit to the bromobenzenes (R² = 0.80, n = 7). The other compounds are predicted by that fit. Compounds are labelled by shorthand. Fit line, slope, intercept and R² are Excel formulas (SLOPE, INTERCEPT, RSQ) over the bromobenzene cells beside the chart.

Sheet gas 09 dG 2e_HDH
A1: min_dG_2e_HDH_kcal | B1: published bromobenzene data | C1: label | D1: y error | G1: min_dG_2e_HDH_kcal | H1: new chlorobenzene data | I1: label | K1: min_dG_2e_HDH_kcal | L1: published PBDE data | M1: label | N1: y error | P1: fit x | Q1: fit: published bromobenzene data
A2: -420.73 | B2: -6.2146 | C2: MonoBr | D2: 0.105 | G2: -419.86 | H2: 1.5559 | I2: HexaCl | K2: -424.42 | L2: -2.551 | M2: BDE-47 | N2: 0.2308 | P2: =MIN($A$2:$A$8) | Q2: =$Q$6+$Q$5*P2
A3: -423.09 | B3: -4.4228 | C3: 1,4-DiBr | D3: 0.1167 | G3: -417.97 | H3: -1.6198 | I3: PentaCl | K3: -425.59 | L3: -0.7985 | M3: BDE-99 | N3: 0.1511 | P3: =MAX($A$2:$A$8) | Q3: =$Q$6+$Q$5*P3
A4: -422.85 | B4: -3.4143 | C4: 1,3-DiBr | D4: 0.0942 | G4: -416.53 | H4: -1.22 | I4: 1,2,4,5-TetraCl
A5: -425.07 | B5: -0.5978 | C5: 1,2,4-TriBr | D5: 0.1491 | G5: -414.55 | H5: -3.15 | I5: 1,2-DiCl | P5: slope | Q5: =SLOPE($B$2:$B$8,$A$2:$A$8)
A6: -424.28 | B6: -0.1054 | C6: 1,3,5-TriBr | D6: 0.1667 | G6: -413.02 | H6: -7.0073 | I6: 1,4-DiCl | P6: intercept | Q6: =INTERCEPT($B$2:$B$8,$A$2:$A$8)
A7: -426.76 | B7: 0.9163 | C7: 1,2,4,5-TetrBr | D7: 0.112 | P7: R2 | Q7: =RSQ($B$2:$B$8,$A$2:$A$8)
A8: -432.03 | B8: 2.3026 | C8: HexaBr | D8: 0.13
S17: Natural logarithm of the observed pseudo-first-order rate constants (k_obs, h⁻¹) for electrochemical dehalogenation at −2.0 V vs SHE [add electrode, cell, electrolyte and pH], plotted against descriptors computed at M06-2X/6-311++G(d), gas phase. Filled gray circles are published bromobenzene data, open circles are new chlorobenzene data and gray squares are published PBDE data. Error bars are ±1 standard error of k_obs propagated to ln k_obs (no standard errors are available for the chlorobenzenes). The dotted line is the least-squares fit to the bromobenzenes (R² = 0.79, n = 7). The other compounds are predicted by that fit. Compounds are labelled by shorthand. Fit line, slope, intercept and R² are Excel formulas (SLOPE, INTERCEPT, RSQ) over the bromobenzene cells beside the chart.

Sheet gas 10 omega_dSCF
A1: omega_dSCF_eV | B1: published bromobenzene data | C1: label | D1: y error | G1: omega_dSCF_eV | H1: new chlorobenzene data | I1: label | K1: omega_dSCF_eV | L1: published PBDE data | M1: label | N1: y error | P1: fit x | Q1: fit: published bromobenzene data
A2: 0.898 | B2: -6.2146 | C2: MonoBr | D2: 0.105 | G2: 1.288 | H2: 1.5559 | I2: HexaCl | K2: 1.098 | L2: -2.551 | M2: BDE-47 | N2: 0.2308 | P2: =MIN($A$2:$A$8) | Q2: =$Q$6+$Q$5*P2
A3: 0.791 | B3: -4.4228 | C3: 1,4-DiBr | D3: 0.1167 | G3: 1.212 | H3: -1.6198 | I3: PentaCl | K3: 1.162 | L3: -0.7985 | M3: BDE-99 | N3: 0.1511 | P3: =MAX($A$2:$A$8) | Q3: =$Q$6+$Q$5*P3
A4: 0.942 | B4: -3.4143 | C4: 1,3-DiBr | D4: 0.0942 | G4: 1.135 | H4: -1.22 | I4: 1,2,4,5-TetraCl
A5: 1.054 | B5: -0.5978 | C5: 1,2,4-TriBr | D5: 0.1491 | G5: 0.905 | H5: -3.15 | I5: 1,2-DiCl | P5: slope | Q5: =SLOPE($B$2:$B$8,$A$2:$A$8)
A6: 1.115 | B6: -0.1054 | C6: 1,3,5-TriBr | D6: 0.1667 | G6: 0.911 | H6: -7.0073 | I6: 1,4-DiCl | P6: intercept | Q6: =INTERCEPT($B$2:$B$8,$A$2:$A$8)
A7: 1.165 | B7: 0.9163 | C7: 1,2,4,5-TetrBr | D7: 0.112 | P7: R2 | Q7: =RSQ($B$2:$B$8,$A$2:$A$8)
A8: 1.534 | B8: 2.3026 | C8: HexaBr | D8: 0.13
S17: Natural logarithm of the observed pseudo-first-order rate constants (k_obs, h⁻¹) for electrochemical dehalogenation at −2.0 V vs SHE [add electrode, cell, electrolyte and pH], plotted against descriptors computed at M06-2X/6-311++G(d), gas phase. Filled gray circles are published bromobenzene data, open circles are new chlorobenzene data and gray squares are published PBDE data. Error bars are ±1 standard error of k_obs propagated to ln k_obs (no standard errors are available for the chlorobenzenes). The dotted line is the least-squares fit to the bromobenzenes (R² = 0.76, n = 7). The other compounds are predicted by that fit. Compounds are labelled by shorthand. Fit line, slope, intercept and R² are Excel formulas (SLOPE, INTERCEPT, RSQ) over the bromobenzene cells beside the chart.

Sheet gas 11 LUMO
A1: LUMO_eV | B1: published bromobenzene data | C1: label | D1: y error | G1: LUMO_eV | H1: new chlorobenzene data | I1: label | K1: LUMO_eV | L1: published PBDE data | M1: label | N1: y error | P1: fit x | Q1: fit: published bromobenzene data
A2: -0.11 | B2: -6.2146 | C2: MonoBr | D2: 0.105 | G2: -0.948 | H2: 1.5559 | I2: HexaCl | K2: -0.723 | L2: -2.551 | M2: BDE-47 | N2: 0.2308 | P2: =MIN($A$2:$A$8) | Q2: =$Q$6+$Q$5*P2
A3: -0.299 | B3: -4.4228 | C3: 1,4-DiBr | D3: 0.1167 | G3: -0.85 | H3: -1.6198 | I3: PentaCl | K3: -0.83 | L3: -0.7985 | M3: BDE-99 | N3: 0.1511 | P3: =MAX($A$2:$A$8) | Q3: =$Q$6+$Q$5*P3
A4: -0.273 | B4: -3.4143 | C4: 1,3-DiBr | D4: 0.0942 | G4: -0.745 | H4: -1.22 | I4: 1,2,4,5-TetraCl
A5: -0.546 | B5: -0.5978 | C5: 1,2,4-TriBr | D5: 0.1491 | G5: -0.158 | H5: -3.15 | I5: 1,2-DiCl | P5: slope | Q5: =SLOPE($B$2:$B$8,$A$2:$A$8)
A6: -0.587 | B6: -0.1054 | C6: 1,3,5-TriBr | D6: 0.1667 | G6: -0.236 | H6: -7.0073 | I6: 1,4-DiCl | P6: intercept | Q6: =INTERCEPT($B$2:$B$8,$A$2:$A$8)
A7: -0.794 | B7: 0.9163 | C7: 1,2,4,5-TetrBr | D7: 0.112 | P7: R2 | Q7: =RSQ($B$2:$B$8,$A$2:$A$8)
A8: -1.601 | B8: 2.3026 | C8: HexaBr | D8: 0.13
S17: Natural logarithm of the observed pseudo-first-order rate constants (k_obs, h⁻¹) for electrochemical dehalogenation at −2.0 V vs SHE [add electrode, cell, electrolyte and pH], plotted against descriptors computed at M06-2X/6-311++G(d), gas phase. Filled gray circles are published bromobenzene data, open circles are new chlorobenzene data and gray squares are published PBDE data. Error bars are ±1 standard error of k_obs propagated to ln k_obs (no standard errors are available for the chlorobenzenes). The dotted line is the least-squares fit to the bromobenzenes (R² = 0.76, n = 7). The other compounds are predicted by that fit. Compounds are labelled by shorthand. Fit line, slope, intercept and R² are Excel formulas (SLOPE, INTERCEPT, RSQ) over the bromobenzene cells beside the chart.

Sheet gas 12 dG 1e
A1: min_dG_1e_kcal | B1: published bromobenzene data | C1: label | D1: y error | G1: min_dG_1e_kcal | H1: new chlorobenzene data | I1: label | K1: min_dG_1e_kcal | L1: published PBDE data | M1: label | N1: y error | P1: fit x | Q1: fit: published bromobenzene data
A2: -8.09 | B2: -6.2146 | C2: MonoBr | D2: 0.105 | G2: -2.78 | H2: 1.5559 | I2: HexaCl | K2: -9.76 | L2: -2.551 | M2: BDE-47 | N2: 0.2308 | P2: =MIN($A$2:$A$8) | Q2: =$Q$6+$Q$5*P2
A3: -8.65 | B3: -4.4228 | C3: 1,4-DiBr | D3: 0.1167 | G3: -1.53 | H3: -1.6198 | I3: PentaCl | K3: -10.15 | L3: -0.7985 | M3: BDE-99 | N3: 0.1511 | P3: =MAX($A$2:$A$8) | Q3: =$Q$6+$Q$5*P3
A4: -9.35 | B4: -3.4143 | C4: 1,3-DiBr | D4: 0.0942 | G4: -0.27 | H4: -1.22 | I4: 1,2,4,5-TetraCl
A5: -10.52 | B5: -0.5978 | C5: 1,2,4-TriBr | D5: 0.1491 | G5: 0.5 | H5: -3.15 | I5: 1,2-DiCl | P5: slope | Q5: =SLOPE($B$2:$B$8,$A$2:$A$8)
A6: -10.28 | B6: -0.1054 | C6: 1,3,5-TriBr | D6: 0.1667 | G6: 1.52 | H6: -7.0073 | I6: 1,4-DiCl | P6: intercept | Q6: =INTERCEPT($B$2:$B$8,$A$2:$A$8)
A7: -11.14 | B7: 0.9163 | C7: 1,2,4,5-TetrBr | D7: 0.112 | P7: R2 | Q7: =RSQ($B$2:$B$8,$A$2:$A$8)
A8: -16.9 | B8: 2.3026 | C8: HexaBr | D8: 0.13
S17: Natural logarithm of the observed pseudo-first-order rate constants (k_obs, h⁻¹) for electrochemical dehalogenation at −2.0 V vs SHE [add electrode, cell, electrolyte and pH], plotted against descriptors computed at M06-2X/6-311++G(d), gas phase. Filled gray circles are published bromobenzene data, open circles are new chlorobenzene data and gray squares are published PBDE data. Error bars are ±1 standard error of k_obs propagated to ln k_obs (no standard errors are available for the chlorobenzenes). The dotted line is the least-squares fit to the bromobenzenes (R² = 0.68, n = 7). The other compounds are predicted by that fit. Compounds are labelled by shorthand. Fit line, slope, intercept and R² are Excel formulas (SLOPE, INTERCEPT, RSQ) over the bromobenzene cells beside the chart.

Sheet gas 13 BDE
A1: min_BDE_kcal | B1: published bromobenzene data | C1: label | D1: y error | G1: min_BDE_kcal | H1: new chlorobenzene data | I1: label | K1: min_BDE_kcal | L1: published PBDE data | M1: label | N1: y error | P1: fit x | Q1: fit: published bromobenzene data
A2: 77.11 | B2: -6.2146 | C2: MonoBr | D2: 0.105 | G2: 91.03 | H2: 1.5559 | I2: HexaCl | K2: 76.05 | L2: -2.551 | M2: BDE-47 | N2: 0.2308 | P2: =MIN($A$2:$A$8) | Q2: =$Q$6+$Q$5*P2
A3: 76.96 | B3: -4.4228 | C3: 1,4-DiBr | D3: 0.1167 | G3: 91.2 | H3: -1.6198 | I3: PentaCl | K3: 75.23 | L3: -0.7985 | M3: BDE-99 | N3: 0.1511 | P3: =MAX($A$2:$A$8) | Q3: =$Q$6+$Q$5*P3
A4: 76.32 | B4: -3.4143 | C4: 1,3-DiBr | D4: 0.0942 | G4: 93.13 | H4: -1.22 | I4: 1,2,4,5-TetraCl
A5: 74.89 | B5: -0.5978 | C5: 1,2,4-TriBr | D5: 0.1491 | G5: 93.47 | H5: -3.15 | I5: 1,2-DiCl | P5: slope | Q5: =SLOPE($B$2:$B$8,$A$2:$A$8)
A6: 75.65 | B6: -0.1054 | C6: 1,3,5-TriBr | D6: 0.1667 | G6: 94.37 | H6: -7.0073 | I6: 1,4-DiCl | P6: intercept | Q6: =INTERCEPT($B$2:$B$8,$A$2:$A$8)
A7: 75.1 | B7: 0.9163 | C7: 1,2,4,5-TetrBr | D7: 0.112 | P7: R2 | Q7: =RSQ($B$2:$B$8,$A$2:$A$8)
A8: 69.97 | B8: 2.3026 | C8: HexaBr | D8: 0.13
S17: Natural logarithm of the observed pseudo-first-order rate constants (k_obs, h⁻¹) for electrochemical dehalogenation at −2.0 V vs SHE [add electrode, cell, electrolyte and pH], plotted against descriptors computed at M06-2X/6-311++G(d), gas phase. Filled gray circles are published bromobenzene data, open circles are new chlorobenzene data and gray squares are published PBDE data. Error bars are ±1 standard error of k_obs propagated to ln k_obs (no standard errors are available for the chlorobenzenes). The dotted line is the least-squares fit to the bromobenzenes (R² = 0.64, n = 7). The other compounds are predicted by that fit. Compounds are labelled by shorthand. Fit line, slope, intercept and R² are Excel formulas (SLOPE, INTERCEPT, RSQ) over the bromobenzene cells beside the chart.

Sheet gas 14 LUMO_RA
A1: LUMO_RA_eV | B1: published bromobenzene data | C1: label | D1: y error | G1: LUMO_RA_eV | H1: new chlorobenzene data | I1: label | K1: LUMO_RA_eV | L1: published PBDE data | M1: label | N1: y error | P1: fit x | Q1: fit: published bromobenzene data
A2: 2.169 | B2: -6.2146 | C2: MonoBr | D2: 0.105 | G2: 2.1696 | H2: 1.5559 | I2: HexaCl | K2: 2.0662 | L2: -2.551 | M2: BDE-47 | N2: 0.2308 | P2: =MIN($A$2:$A$8) | Q2: =$Q$6+$Q$5*P2
A3: 2.427 | B3: -4.4228 | C3: 1,4-DiBr | D3: 0.1167 | G3: 2.1222 | H3: -1.6198 | I3: PentaCl | K3: 1.9143 | L3: -0.7985 | M3: BDE-99 | N3: 0.1511 | P3: =MAX($A$2:$A$8) | Q3: =$Q$6+$Q$5*P3
A4: 2.2403 | B4: -3.4143 | C4: 1,3-DiBr | D4: 0.0942 | G4: 3.0294 | H4: -1.22 | I4: 1,2,4,5-TetraCl
A5: 2.2202 | B5: -0.5978 | C5: 1,2,4-TriBr | D5: 0.1491 | G5: 2.233 | H5: -3.15 | I5: 1,2-DiCl | P5: slope | Q5: =SLOPE($B$2:$B$8,$A$2:$A$8)
A6: 2.1902 | B6: -0.1054 | C6: 1,3,5-TriBr | D6: 0.1667 | G6: 3.0384 | H6: -7.0073 | I6: 1,4-DiCl | P6: intercept | Q6: =INTERCEPT($B$2:$B$8,$A$2:$A$8)
A7: 2.0588 | B7: 0.9163 | C7: 1,2,4,5-TetrBr | D7: 0.112 | P7: R2 | Q7: =RSQ($B$2:$B$8,$A$2:$A$8)
A8: 1.3208 | B8: 2.3026 | C8: HexaBr | D8: 0.13
S17: Natural logarithm of the observed pseudo-first-order rate constants (k_obs, h⁻¹) for electrochemical dehalogenation at −2.0 V vs SHE [add electrode, cell, electrolyte and pH], plotted against descriptors computed at M06-2X/6-311++G(d), gas phase. Filled gray circles are published bromobenzene data, open circles are new chlorobenzene data and gray squares are published PBDE data. Error bars are ±1 standard error of k_obs propagated to ln k_obs (no standard errors are available for the chlorobenzenes). The dotted line is the least-squares fit to the bromobenzenes (R² = 0.44, n = 7). The other compounds are predicted by that fit. Compounds are labelled by shorthand. Fit line, slope, intercept and R² are Excel formulas (SLOPE, INTERCEPT, RSQ) over the bromobenzene cells beside the chart.

Sheet gas 15 dr_CX_RA
A1: max_dr_CX_RA_A | B1: published bromobenzene data | C1: label | D1: y error | G1: max_dr_CX_RA_A | H1: new chlorobenzene data | I1: label | K1: max_dr_CX_RA_A | L1: published PBDE data | M1: label | N1: y error | P1: fit x | Q1: fit: published bromobenzene data
A2: 1.0136 | B2: -6.2146 | C2: MonoBr | D2: 0.105 | G2: 0.0532 | H2: 1.5559 | I2: HexaCl | K2: 0.0103 | L2: -2.551 | M2: BDE-47 | N2: 0.2308 | P2: =MIN($A$2:$A$8) | Q2: =$Q$6+$Q$5*P2
A3: 0.0234 | B3: -4.4228 | C3: 1,4-DiBr | D3: 0.1167 | G3: 0.5429 | H3: -1.6198 | I3: PentaCl | K3: 0.7017 | L3: -0.7985 | M3: BDE-99 | N3: 0.1511 | P3: =MAX($A$2:$A$8) | Q3: =$Q$6+$Q$5*P3
A4: 0.0336 | B4: -3.4143 | C4: 1,3-DiBr | D4: 0.0942 | G4: 0.0483 | H4: -1.22 | I4: 1,2,4,5-TetraCl
A5: 0.6785 | B5: -0.5978 | C5: 1,2,4-TriBr | D5: 0.1491 | G5: 0.7839 | H5: -3.15 | I5: 1,2-DiCl | P5: slope | Q5: =SLOPE($B$2:$B$8,$A$2:$A$8)
A6: 0.7074 | B6: -0.1054 | C6: 1,3,5-TriBr | D6: 0.1667 | G6: 0.0516 | H6: -7.0073 | I6: 1,4-DiCl | P6: intercept | Q6: =INTERCEPT($B$2:$B$8,$A$2:$A$8)
A7: 0.0172 | B7: 0.9163 | C7: 1,2,4,5-TetrBr | D7: 0.112 | P7: R2 | Q7: =RSQ($B$2:$B$8,$A$2:$A$8)
A8: 0.0665 | B8: 2.3026 | C8: HexaBr | D8: 0.13
S17: Natural logarithm of the observed pseudo-first-order rate constants (k_obs, h⁻¹) for electrochemical dehalogenation at −2.0 V vs SHE [add electrode, cell, electrolyte and pH], plotted against descriptors computed at M06-2X/6-311++G(d), gas phase. Filled gray circles are published bromobenzene data, open circles are new chlorobenzene data and gray squares are published PBDE data. Error bars are ±1 standard error of k_obs propagated to ln k_obs (no standard errors are available for the chlorobenzenes). The dotted line is the least-squares fit to the bromobenzenes (R² = 0.11, n = 7). The other compounds are predicted by that fit. Compounds are labelled by shorthand. Fit line, slope, intercept and R² are Excel formulas (SLOPE, INTERCEPT, RSQ) over the bromobenzene cells beside the chart.

Sheet gas 16 fplus_CX
A1: max_fplus_CX | B1: published bromobenzene data | C1: label | D1: y error | G1: max_fplus_CX | H1: new chlorobenzene data | I1: label | K1: max_fplus_CX | L1: published PBDE data | M1: label | N1: y error | P1: fit x | Q1: fit: published bromobenzene data
A2: 0.0911 | B2: -6.2146 | C2: MonoBr | D2: 0.105 | G2: 0.2309 | H2: 1.5559 | I2: HexaCl | K2: 0.1005 | L2: -2.551 | M2: BDE-47 | N2: 0.2308 | P2: =MIN($A$2:$A$8) | Q2: =$Q$6+$Q$5*P2
A3: 0.3699 | B3: -4.4228 | C3: 1,4-DiBr | D3: 0.1167 | G3: 0.2358 | H3: -1.6198 | I3: PentaCl | K3: 0.1321 | L3: -0.7985 | M3: BDE-99 | N3: 0.1511 | P3: =MAX($A$2:$A$8) | Q3: =$Q$6+$Q$5*P3
A4: 0.1425 | B4: -3.4143 | C4: 1,3-DiBr | D4: 0.0942 | G4: 0.1501 | H4: -1.22 | I4: 1,2,4,5-TetraCl
A5: 0.2598 | B5: -0.5978 | C5: 1,2,4-TriBr | D5: 0.1491 | G5: 0.1588 | H5: -3.15 | I5: 1,2-DiCl | P5: slope | Q5: =SLOPE($B$2:$B$8,$A$2:$A$8)
A6: 0.1441 | B6: -0.1054 | C6: 1,3,5-TriBr | D6: 0.1667 | G6: 0.1423 | H6: -7.0073 | I6: 1,4-DiCl | P6: intercept | Q6: =INTERCEPT($B$2:$B$8,$A$2:$A$8)
A7: 0.1556 | B7: 0.9163 | C7: 1,2,4,5-TetrBr | D7: 0.112 | P7: R2 | Q7: =RSQ($B$2:$B$8,$A$2:$A$8)
A8: 0.1667 | B8: 2.3026 | C8: HexaBr | D8: 0.13
S17: Natural logarithm of the observed pseudo-first-order rate constants (k_obs, h⁻¹) for electrochemical dehalogenation at −2.0 V vs SHE [add electrode, cell, electrolyte and pH], plotted against descriptors computed at M06-2X/6-311++G(d), gas phase. Filled gray circles are published bromobenzene data, open circles are new chlorobenzene data and gray squares are published PBDE data. Error bars are ±1 standard error of k_obs propagated to ln k_obs (no standard errors are available for the chlorobenzenes). The dotted line is the least-squares fit to the bromobenzenes (R² = 0.01, n = 7). The other compounds are predicted by that fit. Compounds are labelled by shorthand. Fit line, slope, intercept and R² are Excel formulas (SLOPE, INTERCEPT, RSQ) over the bromobenzene cells beside the chart.

Sheet SMD 01 dG rad_red
A1: min_dG_rad_red_kcal | B1: published bromobenzene data | C1: label | D1: y error | G1: min_dG_rad_red_kcal | H1: new chlorobenzene data | I1: label | K1: min_dG_rad_red_kcal | L1: published PBDE data | M1: label | N1: y error | P1: fit x | Q1: fit: published bromobenzene data
A2: -84.92 | B2: -6.2146 | C2: MonoBr | D2: 0.105 | G2: -114.54 | H2: 1.5559 | I2: HexaCl | K2: -101.22 | L2: -2.551 | M2: BDE-47 | N2: 0.2308 | P2: =MIN($A$2:$A$8) | Q2: =$Q$6+$Q$5*P2
A3: -88.37 | B3: -4.4228 | C3: 1,4-DiBr | D3: 0.1167 | G3: -112.43 | H3: -1.6198 | I3: PentaCl | K3: -108.56 | L3: -0.7985 | M3: BDE-99 | N3: 0.1511 | P3: =MAX($A$2:$A$8) | Q3: =$Q$6+$Q$5*P3
A4: -89.42 | B4: -3.4143 | C4: 1,3-DiBr | D4: 0.0942 | G4: -102.48 | H4: -1.22 | I4: 1,2,4,5-TetraCl
A5: -98.1 | B5: -0.5978 | C5: 1,2,4-TriBr | D5: 0.1491 | G5: -95.61 | H5: -3.15 | I5: 1,2-DiCl | P5: slope | Q5: =SLOPE($B$2:$B$8,$A$2:$A$8)
A6: -94.37 | B6: -0.1054 | C6: 1,3,5-TriBr | D6: 0.1667 | G6: -88.27 | H6: -7.0073 | I6: 1,4-DiCl | P6: intercept | Q6: =INTERCEPT($B$2:$B$8,$A$2:$A$8)
A7: -101.19 | B7: 0.9163 | C7: 1,2,4,5-TetrBr | D7: 0.112 | P7: R2 | Q7: =RSQ($B$2:$B$8,$A$2:$A$8)
A8: -110 | B8: 2.3026 | C8: HexaBr | D8: 0.13
S17: Natural logarithm of the observed pseudo-first-order rate constants (k_obs, h⁻¹) for electrochemical dehalogenation at −2.0 V vs SHE [add electrode, cell, electrolyte and pH], plotted against descriptors computed at M06-2X/6-311++G(d), SMD (water). Filled gray circles are published bromobenzene data, open circles are new chlorobenzene data and gray squares are published PBDE data. Error bars are ±1 standard error of k_obs propagated to ln k_obs (no standard errors are available for the chlorobenzenes). The dotted line is the least-squares fit to the bromobenzenes (R² = 0.89, n = 7). The other compounds are predicted by that fit. Compounds are labelled by shorthand. Fit line, slope, intercept and R² are Excel formulas (SLOPE, INTERCEPT, RSQ) over the bromobenzene cells beside the chart.

Sheet SMD 02 wiberg_CX_parent
A1: min_wiberg_CX_parent | B1: published bromobenzene data | C1: label | D1: y error | G1: min_wiberg_CX_parent | H1: new chlorobenzene data | I1: label | K1: min_wiberg_CX_parent | L1: published PBDE data | M1: label | N1: y error | P1: fit x | Q1: fit: published bromobenzene data
A2: 1.0326 | B2: -6.2146 | C2: MonoBr | D2: 0.105 | G2: 1.0858 | H2: 1.5559 | I2: HexaCl | K2: 1.0374 | L2: -2.551 | M2: BDE-47 | N2: 0.2308 | P2: =MIN($A$2:$A$8) | Q2: =$Q$6+$Q$5*P2
A3: 1.0385 | B3: -4.4228 | C3: 1,4-DiBr | D3: 0.1167 | G3: 1.0752 | H3: -1.6198 | I3: PentaCl | K3: 1.0422 | L3: -0.7985 | M3: BDE-99 | N3: 0.1511 | P3: =MAX($A$2:$A$8) | Q3: =$Q$6+$Q$5*P3
A4: 1.0397 | B4: -3.4143 | C4: 1,3-DiBr | D4: 0.0942 | G4: 1.07 | H4: -1.22 | I4: 1,2,4,5-TetraCl
A5: 1.0447 | B5: -0.5978 | C5: 1,2,4-TriBr | D5: 0.1491 | G5: 1.0577 | H5: -3.15 | I5: 1,2-DiCl | P5: slope | Q5: =SLOPE($B$2:$B$8,$A$2:$A$8)
A6: 1.047 | B6: -0.1054 | C6: 1,3,5-TriBr | D6: 0.1667 | G6: 1.0475 | H6: -7.0073 | I6: 1,4-DiCl | P6: intercept | Q6: =INTERCEPT($B$2:$B$8,$A$2:$A$8)
A7: 1.0553 | B7: 0.9163 | C7: 1,2,4,5-TetrBr | D7: 0.112 | P7: R2 | Q7: =RSQ($B$2:$B$8,$A$2:$A$8)
A8: 1.0656 | B8: 2.3026 | C8: HexaBr | D8: 0.13
S17: Natural logarithm of the observed pseudo-first-order rate constants (k_obs, h⁻¹) for electrochemical dehalogenation at −2.0 V vs SHE [add electrode, cell, electrolyte and pH], plotted against descriptors computed at M06-2X/6-311++G(d), SMD (water). Filled gray circles are published bromobenzene data, open circles are new chlorobenzene data and gray squares are published PBDE data. Error bars are ±1 standard error of k_obs propagated to ln k_obs (no standard errors are available for the chlorobenzenes). The dotted line is the least-squares fit to the bromobenzenes (R² = 0.88, n = 7). The other compounds are predicted by that fit. Compounds are labelled by shorthand. Fit line, slope, intercept and R² are Excel formulas (SLOPE, INTERCEPT, RSQ) over the bromobenzene cells beside the chart.

Sheet SMD 03 n_X
