Workbook

Sheet ReadMe
A1: Haloaromatics QSAR workbook
A3: Purpose | B3: Correlate measured electrochemical dehalogenation rate constants with computed descriptors, to identify which parameters predict reduction kinetics and whether a relationship fitted on the bromobenzenes transfers to the chlorobenzenes and PBDEs.
A4: Rate constants | B4: Pseudo-first-order k_obs (h⁻¹) measured at −2.0 V vs SHE (uncompensated potential, without iR-drop compensation). Bromobenzenes and PBDEs: LaPier et al., Environ. Sci. Technol. 2026, 60, 1346, Table 1 (1,3-dibromobenzene corrected from per day to 0.0329 h⁻¹). Chlorobenzenes: unpublished, no standard errors yet. File: data/experimental_kobs.csv.
A5: Computed data | B5: Gaussian 16, 6-311++G(d). Levels: B3gas = B3LYP/6-311++G(d), gas phase; B3SMD = B3LYP/6-311++G(d), SMD (water); M6gas = M06-2X/6-311++G(d), gas phase; M6SMD = M06-2X/6-311++G(d), SMD (water). Compounds: 7 bromobenzenes, 5 chlorobenzenes, BDE-47 and BDE-99. Built from results/qsar_summary.csv and correlation_data.csv (compile) by figures/qsar_workbook.py.
A6: Tabs | B6: Performance: comparison of all models. Data: every value used. One chart tab per descriptor and level, named <level> <rank by R²> <descriptor>: B3 = B3LYP, M6 = M06-2X, gas or SMD.
A7: Charts and fits | B7: Each chart tab holds the plotted values in cells. The dotted line is the least-squares fit to the bromobenzenes computed by Excel (SLOPE, INTERCEPT, RSQ in the cells beside the chart), so editing a value updates the line and statistics. Filled gray circles: published bromobenzene data (fitted). Open circles: new chlorobenzene data (predicted). Gray squares: published PBDE data (predicted). Error bars: ±1 standard error of k_obs propagated to ln k_obs (SE/k_obs). Site descriptors use the most favourable C–X site of each compound (min_ / max_) or a degeneracy-weighted effective value (eff_).
A9: Calculated parameters
A10: descriptor | B10: key | C10: units | D10: definition / how computed | E10: significance for reduction kinetics | F10: availability | G10: set
A11: LUMO of ArX | B11: LUMO_eV | C11: eV | D11: Energy of the lowest unoccupied molecular orbital of the neutral parent ArX (lowest of the alpha/beta virtual orbitals). | E11: Frontier-orbital estimate of how easily ArX accepts an electron: a lower LUMO means easier reduction. Cheap, but virtual-orbital energies depend on the functional and on diffuse functions, so it is a qualitative proxy for the electron affinity. | F11: All compounds, all levels. | G11: thermo
A12: LUMO of the radical anion ArX•⁻ | B12: LUMO_RA_eV | C12: eV | D12: LUMO of the relaxed radical anion ArX•⁻ in whatever state it optimised to (π, bent σ, or dissociated Ar•···X⁻ complex). | E12: How easily the radical anion takes a second electron (2-electron pathway). | F12: All compounds; meaning changes when the radical anion is dissociated. | G12: thermo
A13: ΔG ArX + e⁻ → Ar• + X⁻ | B13: min_dG_1e_kcal | C13: kcal/mol | D13: ΔG of ArX + e⁻ → Ar• + X⁻ at the most favourable C–X site (concerted dissociative one-electron reduction). | E13: Driving force of the concerted dissociative electron transfer (Savéant). Its standard potential is E°_DET. | F13: All compounds, all levels. | G13: thermo
A14: ΔG ArX + 2e⁻ → Ar⁻ + X⁻ | B14: min_dG_2e_carbanion_kcal | C14: kcal/mol | D14: ΔG of ArX + 2e⁻ → Ar⁻ + X⁻ at the most favourable site. | E14: Overall driving force of two-electron reductive C–X cleavage to the aryl carbanion (which is protonated to ArH). | F14: All compounds, all levels. | G14: thermo
A15: ΔG ArX + e⁻ → ArX•⁻ | B15: dG_ET_any_kcal | C15: kcal/mol | D15: ΔG of ArX + e⁻ → ArX•⁻, using the lowest radical-anion energy whatever its structure. | E15: Driving force of the first electron transfer (stepwise pathway). Where the radical anion is dissociated this already includes C–X cleavage. | F15: All compounds, all levels. | G15: thermo
A16: ΔG ArX•⁻ → Ar• + X⁻ | B16: min_dG_frag_any_kcal | C16: kcal/mol | D16: ΔG of ArX•⁻ → Ar• + X⁻ from the lowest radical-anion energy, most favourable site. | E16: Driving force of radical-anion fragmentation (second step of the stepwise pathway). | F16: All compounds, all levels. | G16: thermo
A17: ΔG ArX•⁻ + e⁻ → Ar⁻ + X⁻ | B17: min_dG_RA_2e_any_kcal | C17: kcal/mol | D17: ΔG of ArX•⁻ + e⁻ → Ar⁻ + X⁻ (second electron to the radical anion with C–X cleavage), most favourable site. | E17: Driving force of the second reduction in a 2-electron stepwise path. | F17: All compounds, all levels. | G17: thermo
A18: number of halogens | B18: n_X | C18: - | D18: Number of halogen substituents. | E18: Structural baseline: most electronic descriptors increase with n_X, so a descriptor that does no better than n_X adds little physical insight. | F18: All compounds. | G18: extended
A19: vertical electron affinity | B19: VEA_eV | C19: eV | D19: Vertical electron affinity E(ArX) − E(ArX•⁻), both at the neutral geometry (ΔSCF single points; electronic energies). | E19: Energy released on adding an electron without nuclear relaxation, i.e. the Franck–Condon step of heterogeneous electron transfer. Positive = electron is bound. | F19: All compounds, all levels (sp stage). | G19: extended
A20: adiabatic electron affinity (electronic) | B20: AEA_elec_eV | C20: eV | D20: Adiabatic electron affinity E(ArX) − E(ArX•⁻), each at its own optimised geometry (electronic energies). | E20: Thermodynamic electron affinity including relaxation. | F20: Only where the radical anion is bound (π or bent σ): few bromobenzenes at M06-2X. | G20: extended
A21: electrophilicity index (ΔSCF) | B21: omega_dSCF_eV | C21: eV | D21: Parr electrophilicity index ω = μ²/(2η) with μ = −(VIE + VEA)/2 and η = VIE − VEA from ΔSCF vertical ionisation energy and electron affinity. | E21: Global propensity to accept electron density; combines electron affinity and hardness. | F21: All compounds, all levels (sp stage). | G21: extended
... A24: ΔG ArX•⁻ → Ar• + X⁻, bound radical anion only | B24: min_dG_frag_kcal | C24: kcal/mol | D24: As min_dG_frag_any, bound radical anions only. | E24: Fragmentation of a genuine intermediate. | F24: Bound radical anions only. | G24: extended
A25: ΔG ArX•⁻ + e⁻ → Ar⁻ + X⁻, bound radical anion only | B25: min_dG_RA_2e_kcal | C25: kcal/mol | D25: As min_dG_RA_2e_any, bound radical anions only. | F25: Bound radical anions only. | G25: extended
A26: ΔG ArX + H⁺ + 2e⁻ → ArH + X⁻ | B26: min_dG_2e_HDH_kcal | C26: kcal/mol | D26: ΔG of ArX + H⁺ + 2e⁻ → ArH + X⁻ (hydrodehalogenation), most favourable site. | E26: Overall driving force of the observed net reaction (the aryl carbanion is protonated). | F26: All compounds, all levels. | G26: extended
A27: ΔG Ar• + e⁻ → Ar⁻ | B27: min_dG_rad_red_kcal | C27: kcal/mol | D27: ΔG of Ar• + e⁻ → Ar⁻ for the aryl radical formed at the most favourable site. | E27: Reducibility of the aryl radical: decides whether the radical is reduced further (2e path) or reacts otherwise (H-abstraction, dimerisation). | F27: All compounds, all levels. | G27: extended
A28: inner-sphere reorganisation energy | B28: lambda_i_kcal | C28: kcal/mol | D28: Nelsen four-point inner-sphere reorganisation energy of the ArX/ArX•⁻ couple, λ_i = [E(N@A) − E(N@N)] + [E(A@N) − E(A@A)]. | E28: Inner-sphere contribution to the Marcus electron-transfer barrier (λ/4 at zero driving force). | F28: π radical anions only. | G28: extended
A29: weakest C–X bond enthalpy | B29: min_BDE_kcal | C29: kcal/mol | D29: Weakest homolytic C–X bond enthalpy D = H(Ar•) + H(X•) − H(ArX), with the ²P₃/₂ spin–orbit correction of X•. | E29: Bond strength that the concerted pathway must overcome; D enters the Savéant intrinsic barrier. | F29: All compounds, all levels. | G29: extended
A30: Savéant intrinsic barrier (weakest C–X) | B30: min_dG0_act_concerted_kcal | C30: kcal/mol | D30: Savéant intrinsic barrier ΔG₀‡ = (D + λ₀)/4 for the weakest bond; λ₀ from the Marcus–Hush one-sphere model. | E30: Barrier of concerted dissociative electron transfer at zero driving force. | F30: SMD levels only. | G30: extended
A31: Savéant concerted barrier | B31: eff_dG_act_concerted_kcal @ -2.00 V | C31: kcal/mol | D31: Savéant concerted barrier ΔG‡(E) = ΔG₀‡(1 + ΔG°(E)/4ΔG₀‡)² at E = −2.0 V, combined over sites as −RT ln Σ g_i exp(−ΔG‡_i/RT). | E31: Predicted activation free energy of the concerted pathway at the experimental potential; transition-state theory predicts a slope of −1/RT (see slope×RT). | F31: SMD levels only. | G31: extended
A32: stepwise ET + cleavage barrier | B32: eff_dG_act_stepwise_kcal @ -2.00 V | C32: kcal/mol | D32: Stepwise barrier: max of the ET barrier and ET + fragmentation TS, degeneracy-weighted. | F32: Needs the TS stage (not run for these compounds). | G32: extended
A33: combined stepwise + concerted | B33: eff_dG_act_combined_kcal @ -2.00 V | C33: kcal/mol | D33: Effective barrier combining the stepwise and concerted rates. | E33: Without TS barriers this equals the concerted barrier. | F33: SMD levels only. | G33: extended
A34: C–X cleavage TS barrier of ArX•⁻ | B34: eff_dG_act_frag_TS_kcal | C34: kcal/mol | D34: C–X cleavage TS barrier of the radical anion. | F34: Needs the TS stage (not run). | G34: extended
A35: largest Fukui f+ on a C–X bond | B35: max_fplus_CX | C35: e | D35: Largest condensed Fukui function f⁺ on a C–X bond (C + X), f⁺ = q_Hirshfeld(ArX) − q_Hirshfeld(ArX•⁻ at the neutral geometry). | E35: How much of the incoming electron lands on a C–X bond: a site-reactivity index for reductive cleavage. | F35: All compounds, all levels (sp stage). | G35: extended
A36: weakest Wiberg C–X bond order | B36: min_wiberg_CX_parent | C36: - | D36: Smallest Wiberg C–X bond index of the neutral parent (NBO, NAO basis). | E36: Weaker (lower-order) C–X bonds should break more easily. | F36: All compounds, all levels (sp stage). | G36: extended
A37: largest halogen spin density in ArX•⁻ | B37: max_spin_RA_X | C37: e | D37: Largest Hirshfeld spin density on a halogen in the relaxed radical anion. | E37: σ* character: spin on X means the extra electron sits in the C–X σ* orbital. | F37: Bound radical anions only (sp of the radical anion). | G37: extended
A38: largest C–X elongation in ArX•⁻ | B38: max_dr_CX_RA_A | C38: Å | D38: Largest C–X lengthening in the relaxed radical anion relative to the parent. | E38: Degree of C–X σ* occupation; very large values mean the radical anion dissociated. | F38: All compounds, all levels. | G38: extended
A40: Statistics
A41: statistic | B41: definition | C41: how to read it | D41: caveats
A42: n | B42: Number of compounds in the fit. | C42: Bromobenzene fits have n = 7; chlorobenzenes n = 5; halobenzenes n = 12; all n = 14. | D42: With n = 7, one unusual compound can dominate a fit.
A43: slope, intercept | B43: Ordinary least squares: ln k_obs = slope·x + intercept. | C43: The slope sign shows the direction: for ΔG descriptors a negative slope means more exergonic → faster. | D43: Units: ln(h⁻¹) per descriptor unit.
A44: r, R² | B44: Pearson correlation and coefficient of determination R² = 1 − SSE/SST, SST = Σ(ln k − mean)². | C44: Fraction of the variance of ln k_obs in the fitted set explained by the line (0 to 1). | D44: Describes the fit, not its predictive power; R² never decreases when predictors are added.
A45: p | B45: Two-sided t-test of slope = 0 with n − 2 degrees of freedom. | C45: Probability of an |r| this large if there were no linear relationship. | D45: Not corrected for multiple testing: this workbook tests ~70 descriptor × level combinations, so about 3–4 would reach p < 0.05 by chance. The Bonferroni column uses 0.05/(number of fits).
...

Sheet Performance
A1: QSAR performance: ln k_obs vs computed descriptors (single-descriptor fits on the bromobenzenes, n = 7)
A2: Ranked by leave-one-out Q² (predictive ability). R² describes the fit; Q² tests it by predicting each bromobenzene from the other six; ext RMSE applies the bromobenzene line to the chlorobenzenes and PBDEs, which were not used in the fit. RMSE values are in ln k units (1 = factor 2.7 in k_obs). Bonferroni p threshold for 69 fits: 7.2e-04. Definitions on the ReadMe tab.
A4: 1. Top 10 models (all levels)
A5: rank | B5: level | C5: descriptor | D5: R² | E5: Q² | F5: RMSE | G5: LOO RMSE | H5: ext RMSE | I5: p | J5: p < Bonferroni | K5: R² halobenzenes (n=12) | L5: chart tab
A6: 1 | B6: M6gas | C6: ΔG ArX•⁻ + e⁻ → Ar⁻ + X⁻ | D6: 0.9306 | E6: 0.8854 | F6: 0.7541 | G6: 0.9687 | H6: 4.085 | I6: 0.0004 | J6: yes | K6: 0.5516 | L6: M6gas 02 dG RA_2e_any
A7: 2 | B7: B3gas | C7: ΔG ArX•⁻ + e⁻ → Ar⁻ + X⁻ | D7: 0.9225 | E7: 0.8686 | F7: 0.7966 | G7: 1.0374 | H7: 4.418 | I7: 0.0006 | J7: yes | K7: 0.4603 | L7: B3gas 02 dG RA_2e_any
A8: 3 | B8: B3gas | C8: ΔG Ar• + e⁻ → Ar⁻ | D8: 0.9473 | E8: 0.8653 | F8: 0.6572 | G8: 1.0504 | H8: 2.671 | I8: 0.0002 | J8: yes | K8: 0.7843 | L8: B3gas 01 dG rad_red
A9: 4 | B9: M6gas | C9: ΔG Ar• + e⁻ → Ar⁻ | D9: 0.9375 | E9: 0.8531 | F9: 0.7155 | G9: 1.097 | H9: 2.831 | I9: 0.0003 | J9: yes | K9: 0.772 | L9: M6gas 01 dG rad_red
A10: 5 | B10: M6gas | C10: ΔG ArX + 2e⁻ → Ar⁻ + X⁻ | D10: 0.9152 | E10: 0.7496 | F10: 0.8333 | G10: 1.4322 | H10: 1.887 | I10: 0.0007 | J10: yes | K10: 0.8748 | L10: M6gas 04 dG 2e_carbanion
A11: 6 | B11: B3gas | C11: ΔG ArX•⁻ → Ar• + X⁻ | D11: 0.9217 | E11: 0.7459 | F11: 0.8009 | G11: 1.4426 | H11: 2.058 | I11: 0.0006 | J11: yes | K11: 0.8568 | L11: B3gas 03 dG frag_any
A12: 7 | B12: B3SMD | C12: ΔG ArX•⁻ + e⁻ → Ar⁻ + X⁻ | D12: 0.8928 | E12: 0.7358 | F12: 0.937 | G12: 1.4711 | H12: 7.158 | I12: 0.0013 | J12: no | K12: 0.0768 | L12: B3SMD 02 dG RA_2e_any
A13: 8 | B13: B3gas | C13: ΔG ArX + 2e⁻ → Ar⁻ + X⁻ | D13: 0.9131 | E13: 0.722 | F13: 0.8438 | G13: 1.509 | H13: 1.77 | I13: 0.0008 | J13: no | K13: 0.8657 | L13: B3gas 05 dG 2e_carbanion
A14: 9 | B14: M6gas | C14: ΔG ArX•⁻ → Ar• + X⁻ | D14: 0.9175 | E14: 0.7183 | F14: 0.822 | G14: 1.5191 | H14: 1.927 | I14: 0.0007 | J14: yes | K14: 0.8357 | L14: M6gas 03 dG frag_any
A15: 10 | B15: B3gas | C15: LUMO of the radical anion ArX•⁻ | D15: 0.9211 | E15: 0.717 | F15: 0.8039 | G15: 1.5226 | H15: 1.584 | I15: 0.0006 | J15: yes | K15: 0.8779 | L15: B3gas 04 LUMO_RA
A18: 2. Descriptor × level comparison (bromobenzene fits)
A19: Bold = best value in that column. Blank = too few compounds with data at that level.
A20: descriptor | B20: set | C20: B3gas R² | D20: B3SMD R² | E20: M6gas R² | F20: M6SMD R² | G20: B3gas Q² | H20: B3SMD Q² | I20: M6gas Q² | J20: M6SMD Q² | K20: B3gas ext RMSE | L20: B3SMD ext RMSE | M20: M6gas ext RMSE | N20: M6SMD ext RMSE | O20: B3gas R² halo | P20: B3SMD R² halo | Q20: M6gas R² halo | R20: M6SMD R² halo
A21: LUMO of ArX | B21: thermo | C21: 0.8427 | D21: 0.8437 | E21: 0.7588 | F21: 0.7412 | G21: 0.2816 | H21: 0.2325 | I21: -0.4638 | J21: -0.6612 | K21: 1.541 | L21: 1.377 | M21: 1.623 | N21: 1.49 | O21: 0.7605 | P21: 0.7856 | Q21: 0.7078 | R21: 0.7094
A22: LUMO of the radical anion ArX•⁻ | B22: thermo | C22: 0.9211 | D22: 0.7559 | E22: 0.4408 | F22: 0.1122 | G22: 0.717 | H22: 0.2752 | I22: -0.3728 | J22: -0.7702 | K22: 1.584 | L22: 7.304 | M22: 2.65 | N22: 1.963 | O22: 0.8779 | P22: 0.4134 | Q22: 0.3335 | R22: 0.2168
A23: ΔG ArX + e⁻ → Ar• + X⁻ | B23: thermo | C23: 0.6614 | D23: 0.6779 | E23: 0.6766 | F23: 0.7086 | G23: -1.6937 | H23: -0.7484 | I23: -2.1303 | J23: -0.7651 | K23: 4.201 | L23: 3.362 | M23: 7.083 | N23: 2.993 | O23: 0.3486 | P23: 0.3666 | Q23: 0.1941 | R23: 0.4351
A24: ΔG ArX + 2e⁻ → Ar⁻ + X⁻ | B24: thermo | C24: 0.9131 | D24: 0.8416 | E24: 0.9152 | F24: 0.8592 | G24: 0.722 | H24: 0.4375 | I24: 0.7496 | J24: 0.5379 | K24: 1.77 | L24: 3.16 | M24: 1.887 | N24: 3.122 | O24: 0.8657 | P24: 0.5854 | Q24: 0.8748 | R24: 0.6139
A25: ΔG ArX + e⁻ → ArX•⁻ | B25: thermo | C25: 0.8571 | D25: 0.7489 | E25: 0.8662 | F25: 0.4856 | G25: 0.311 | H25: -0.253 | I25: 0.402 | J25: -0.9527 | K25: 1.723 | L25: 3.474 | M25: 2.164 | N25: 1.905 | O25: 0.8371 | P25: 0.6344 | Q25: 0.7717 | R25: 0.4882
A26: ΔG ArX•⁻ → Ar• + X⁻ | B26: thermo | C26: 0.9217 | D26: 0.8027 | E26: 0.9175 | F26: 0.3153 | G26: 0.7459 | H26: 0.526 | I26: 0.7183 | J26: -6.7526 | K26: 2.058 | L26: 13.058 | M26: 1.927 | N26: 2.161 | O26: 0.8568 | P26: 0.4269 | Q26: 0.8357 | R26: 0.3475
A27: ΔG ArX•⁻ + e⁻ → Ar⁻ + X⁻ | B27: thermo | C27: 0.9225 | D27: 0.8928 | E27: 0.9306 | F27: 0.1955 | G27: 0.8686 | H27: 0.7358 | I27: 0.8854 | J27: -1.3665 | K27: 4.418 | L27: 7.158 | M27: 4.085 | N27: 3.789 | O27: 0.4603 | P27: 0.0768 | Q27: 0.5516 | R27: 0.0294
A28: number of halogens | B28: extended | C28: 0.8601 | D28: 0.8601 | E28: 0.8601 | F28: 0.8601 | G28: 0.4698 | H28: 0.4698 | I28: 0.4698 | J28: 0.4698 | K28: 2.545 | L28: 2.545 | M28: 2.545 | N28: 2.545 | O28: 0.7082 | P28: 0.7082 | Q28: 0.7082 | R28: 0.7082
A29: vertical electron affinity | B29: extended | C29: 0.8015 | D29: 0.7452 | E29: 0.8029 | F29: 0.8275 | G29: 0.37 | H29: -0.4275 | I29: 0.4874 | J29: 0.2059 | K29: 1.619 | L29: 1.655 | M29: 1.806 | N29: 1.696 | O29: 0.7332 | P29: 0.678 | Q29: 0.7374 | R29: 0.7322
A30: electrophilicity index (ΔSCF) | B30: extended | C30: 0.7379 | D30: 0.6786 | E30: 0.7629 | F30: 0.7953 | G30: -0.0455 | H30: -1.5279 | I30: 0.2394 | J30: -0.1301 | K30: 1.519 | L30: 1.719 | M30: 1.577 | N30: 1.638 | O30: 0.6953 | P30: 0.6268 | Q30: 0.7188 | R30: 0.7301
A31: ΔG ArX + H⁺ + 2e⁻ → ArH + X⁻ | B31: extended | C31: 0.7562 | D31: 0.785 | E31: 0.7853 | F31: 0.8172 | G31: 0.0213 | H31: 0.3003 | I31: 0.0999 | J31: 0.3868 | K31: 3.233 | L31: 3.994 | M31: 5.036 | N31: 3.51 | O31: 0.5178 | P31: 0.3842 | Q31: 0.3672 | R31: 0.4663
A32: ΔG Ar• + e⁻ → Ar⁻ | B32: extended | C32: 0.9473 | D32: 0.8933 | E32: 0.9375 | F32: 0.8924 | G32: 0.8653 | H32: 0.6844 | I32: 0.8531 | J32: 0.7114 | K32: 2.671 | L32: 3.301 | M32: 2.831 | N32: 3.432 | O32: 0.7843 | P32: 0.653 | Q32: 0.772 | R32: 0.6424
A33: weakest C–X bond enthalpy | B33: extended | C33: 0.6258 | D33: 0.6652 | E33: 0.6389 | F33: 0.7007 | G33: -1.3979 | H33: -0.9488 | I33: -2.0922 | J33: -1.0808 | K33: 8.143 | L33: 8.508 | M33: 14.539 | N33: 15.162 | O33: 0.1575 | P33: 0.1602 | Q33: 0.0775 | R33: 0.0822
A34: Savéant intrinsic barrier (weakest C–X) | B34: extended | D34: 0.7878 | F34: 0.8285 | H34: -0.0947 | J34: 0.1375 | L34: 6.197 | N34: 9.533 | P34: 0.3017 | R34: 0.1888
A35: Savéant concerted barrier | B35: extended | D35: 0.7709 | F35: 0.8007 | H35: -0.2348 | J35: -0.0434 | L35: 1.482 | N35: 2.672 | P35: 0.7556 | R35: 0.6003
A36: combined stepwise + concerted | B36: extended | F36: 0.8007 | J36: -0.0434 | N36: 2.672 | R36: 0.6003
A37: largest Fukui f+ on a C–X bond | B37: extended | C37: 0.035 | D37: 0.161 | E37: 0.0066 | F37: 0.5331 | G37: -1.584 | H37: -3.1062 | I37: -2.112 | J37: 0.1795 | K37: 2.754 | L37: 2.089 | M37: 2.549 | N37: 5.003 | O37: 0.005 | P37: 0.2479 | Q37: 0.0119 | R37: 0.3151
A38: weakest Wiberg C–X bond order | B38: extended | C38: 0.8463 | D38: 0.8813 | E38: 0.8583 | F38: 0.8822 | G38: 0.5788 | H38: 0.6733 | I38: 0.6136 | J38: 0.6738 | K38: 7.403 | L38: 5.46 | M38: 7.137 | N38: 5.318 | O38: 0.2244 | P38: 0.3776 | Q38: 0.2466 | R38: 0.3934
A39: largest C–X elongation in ArX•⁻ | B39: extended | C39: 0.3399 | D39: 0.2416 | E39: 0.1135 | F39: 0.31 | G39: -0.3259 | H39: -0.8336 | I39: -0.9953 | J39: -1.063 | K39: 3.101 | L39: 5.995 | M39: 2.673 | N39: 2.77 | O39: 0.1292 | P39: 0.0266 | Q39: 0.0518 | R39: 0.1161
A42: 3. All single-descriptor fits (sorted by Q²)
A43: level | B43: descriptor | C43: key | D43: set | E43: n | F43: R² (live) | G43: slope (live) | H43: R² | I43: Q² | J43: slope | K43: intercept | L43: p | M43: RMSE | N43: LOO RMSE | O43: ext RMSE | P43: slope×RT | Q43: R² chlorobenzenes (n=5) | R43: R² halobenzenes (n=12) | S43: R² all (n=14) | T43: chart tab
A44: M6gas | B44: ΔG ArX•⁻ + e⁻ → Ar⁻ + X⁻ | C44: min_dG_RA_2e_any_kcal | D44: thermo | E44: 7 | F44: ='M6gas 02 dG RA_2e_any'!Q7 | G44: ='M6gas 02 dG RA_2e_any'!Q5 | H44: 0.9306 | I44: 0.8854 | J44: -0.3432 | K44: -13.9074 | L44: 0.0004 | M44: 0.7541 | N44: 0.9687 | O44: 4.085 | Q44: 0.5895 | R44: 0.5516 | S44: 0.4478 | T44: M6gas 02 dG RA_2e_any
A45: B3gas | B45: ΔG ArX•⁻ + e⁻ → Ar⁻ + X⁻ | C45: min_dG_RA_2e_any_kcal | D45: thermo | E45: 7 | F45: ='B3gas 02 dG RA_2e_any'!Q7 | G45: ='B3gas 02 dG RA_2e_any'!Q5 | H45: 0.9225 | I45: 0.8686 | J45: -0.3184 | K45: -13.3101 | L45: 0.0006 | M45: 0.7966 | N45: 1.0374 | O45: 4.418 | Q45: 0.2571 | R45: 0.4603 | S45: 0.3482 | T45: B3gas 02 dG RA_2e_any
...

Sheet Data
A1: level | B1: compound | C1: label | D1: species | E1: group | F1: kobs (1/h) | G1: SE (1/h) | H1: ln kobs | I1: LUMO_eV | J1: LUMO_RA_eV | K1: min_dG_1e_kcal | L1: min_dG_2e_carbanion_kcal | M1: dG_ET_any_kcal | N1: min_dG_frag_any_kcal | O1: min_dG_RA_2e_any_kcal | P1: n_X | Q1: VEA_eV | R1: AEA_elec_eV | S1: omega_dSCF_eV | T1: E_ET_V | U1: dG_ET_kcal | V1: min_dG_frag_kcal | W1: min_dG_RA_2e_kcal | X1: min_dG_2e_HDH_kcal | Y1: min_dG_rad_red_kcal | Z1: lambda_i_kcal | AA1: min_BDE_kcal | AB1: min_dG0_act_concerted_kcal | AC1: eff_dG_act_concerted_kcal @ -2.00 V | AD1: eff_dG_act_combined_kcal @ -2.00 V | AE1: max_fplus_CX | AF1: min_wiberg_CX_parent | AG1: max_spin_RA_X | AH1: max_dr_CX_RA_A
A2: B3gas | B2: Bromobenzene | C2: MonoBr | D2: BrBz_1 | E2: bromobenzene | F2: 0.002 | G2: 0.00021 | H2: -6.2146 | I2: -0.84 | J2: 2.0743 | K2: -13.36 | L2: -37.3 | M2: -12.91 | N2: -0.45 | O2: -24.39 | P2: 1 | Q2: -0.449 | S2: 0.957 | X2: -427.77 | Y2: -23.94 | AA2: 74.12 | AE2: 0.1498 | AF2: 1.0359 | AH2: 0.9262
A3: B3gas | B3: 1,4-Dibromobenzene | C3: 1,4-DiBr | D3: BrBz_14 | E3: bromobenzene | F3: 0.012 | G3: 0.0014 | H3: -4.4228 | I3: -1.201 | J3: 1.96 | K3: -13.77 | L3: -47.41 | M3: -18.93 | N3: 5.16 | O3: -28.48 | P3: 2 | Q3: -0.671 | S3: 0.863 | X3: -430.06 | Y3: -33.64 | AA3: 74.12 | AE3: 0.4011 | AF3: 1.0408 | AH3: 0.8605
A4: B3gas | B4: 1,3-Dibromobenzene | C4: 1,3-DiBr | D4: BrBz_13 | E4: bromobenzene | F4: 0.0329 | G4: 0.0031 | H4: -3.4143 | I4: -1.19 | J4: 1.6376 | K4: -14.58 | L4: -50.97 | M4: -19.99 | N4: 5.41 | O4: -30.98 | P4: 2 | Q4: -0.222 | S4: 1.032 | X4: -429.7 | Y4: -36.39 | AA4: 73.33 | AE4: 0.2248 | AF4: 1.0417 | AH4: 0.0475
A5: B3gas | B5: 1,2,4-Tribromobenzene | C5: 1,2,4-TriBr | D5: BrBz_124 | E5: bromobenzene | F5: 0.55 | G5: 0.082 | H5: -0.5978 | I5: -1.525 | J5: 1.2517 | K5: -16.77 | L5: -69.17 | M5: -26.74 | N5: 9.97 | O5: -42.44 | P5: 3 | Q5: 0.063 | S5: 1.118 | X5: -432.76 | Y5: -52.41 | AA5: 70.93 | AE5: 0.271 | AF5: 1.0452 | AH5: 0.7235
A6: B3gas | B6: 1,3,5-Tribromobenzene | C6: 1,3,5-TriBr | D6: BrBz_135 | E6: bromobenzene | F6: 0.9 | G6: 0.15 | H6: -0.1054 | I6: -1.638 | J6: 1.1129 | K6: -15.54 | L6: -63.39 | M6: -27.39 | N6: 11.86 | O6: -36 | P6: 3 | Q6: 0.164 | S6: 1.199 | X6: -431.09 | Y6: -47.86 | AA6: 72.64 | AE6: 0.2669 | AF6: 1.0465 | AH6: 0.7132
A7: B3gas | B7: 1,2,4,5-Tetrabromobenzene | C7: 1,2,4,5-TetrBr | D7: BrBz_1245 | E7: bromobenzene | F7: 2.5 | G7: 0.28 | H7: 0.9163 | I7: -1.863 | J7: 0.9924 | K7: -17.23 | L7: -74.6 | M7: -30.89 | N7: 13.66 | O7: -43.71 | P7: 4 | Q7: 0.417 | S7: 1.257 | X7: -434.37 | Y7: -57.37 | AA7: 71.28 | AE7: 0.214 | AF7: 1.0544 | AH7: 0.0198
A8: B3gas | B8: Hexabromobenzene | C8: HexaBr | D8: BrBz_123456 | E8: bromobenzene | F8: 10 | G8: 1.3 | H8: 2.3026 | I8: -2.723 | J8: 0.2231 | K8: -24.73 | L8: -97.23 | M8: -46.83 | N8: 22.11 | O8: -50.39 | P8: 6 | Q8: 1.313 | R8: 1.787 | S8: 1.709 | U8: -46.83 | V8: 22.11 | W8: -50.39 | X8: -440.64 | Y8: -72.5 | Z8: 23.67 | AA8: 64.31 | AE8: 0.1667 | AF8: 1.0634 | AG8: 0.10526 | AH8: 0.0908
A9: B3gas | B9: BDE-47 | C9: BDE-47 | D9: BDE_24_24 | E9: pbde | F9: 0.078 | G9: 0.018 | H9: -2.551 | I9: -1.575 | J9: 1.0397 | K9: -15.72 | L9: -74.87 | M9: -28.49 | N9: 12.77 | O9: -46.38 | P9: 4 | Q9: 0.235 | S9: 1.099 | X9: -432.05 | Y9: -59.15 | AA9: 71.61 | AE9: 0.1206 | AF9: 1.0412 | AH9: 0.0135
A10: B3gas | B10: BDE-99 | C10: BDE-99 | D10: BDE_245_24 | E10: pbde | F10: 0.45 | G10: 0.068 | H10: -0.7985 | I10: -1.69 | J10: 0.7611 | K10: -16.39 | L10: -85.28 | M10: -23.93 | N10: 7.54 | O10: -61.35 | P10: 5 | Q10: 0.41 | S10: 1.192 | X10: -433.68 | Y10: -69.6 | AA10: 71.31 | AE10: 0.1534 | AF10: 1.0454 | AH10: 0.7027
A11: B3gas | B11: Hexachlorobenzene | C11: HexaCl | D11: ClBz_123456 | E11: chlorobenzene | F11: 4.7393042 | H11: 1.5559 | I11: -1.995 | J11: 0.9818 | K11: -11.63 | L11: -83.08 | M11: -34.01 | N11: 22.38 | O11: -49.07 | P11: 6 | Q11: 0.256 | R11: 1.225 | S11: 1.244 | U11: -34.01 | V11: 22.38 | W11: -49.07 | X11: -429.78 | Y11: -71.45 | Z11: 40.2 | AA11: 83.09 | AE11: 0.2258 | AF11: 1.0891 | AG11: 0.07279 | AH11: 0.0719
A12: B3gas | B12: Pentachlorobenzene | C12: PentaCl | D12: ClBz_12345 | E12: chlorobenzene | F12: 0.19793594 | H12: -1.6198 | I12: -1.785 | J12: 0.9665 | K12: -10.39 | L12: -78.49 | M12: -28.12 | N12: 17.74 | O12: -50.37 | P12: 5 | Q12: 0.106 | R12: 1.067 | S12: 1.174 | U12: -28.12 | V12: 17.74 | W12: -50.37 | X12: -427.83 | Y12: -68.1 | Z12: 69.83 | AA12: 83.27 | AE12: 0.2291 | AF12: 1.0783 | AG12: 0.36682 | AH12: 0.6122
A13: B3gas | B13: 1,2,4,5-Tetrachlorobenzene | C13: 1,2,4,5-TetraCl | D13: ClBz_1245 | E13: chlorobenzene | F13: 0.29523017 | H13: -1.22 | I13: -1.67 | J13: 1.4713 | K13: -7.63 | L13: -62.59 | M13: -21.44 | N13: 13.81 | O13: -41.14 | P13: 4 | Q13: -0.052 | S13: 1.103 | X13: -425.53 | Y13: -54.95 | AA13: 86.63 | AE13: 0.1526 | AF13: 1.0754 | AH13: 0.0451
A14: B3gas | B14: 1,2-Dichlorobenzene | C14: 1,2-DiCl | D14: ClBz_12 | E14: chlorobenzene | F14: 0.042852127 | H14: -3.15 | I14: -1.1 | J14: 1.8912 | K14: -7.02 | L14: -47.71 | M14: -11.69 | N14: 4.67 | O14: -36.01 | P14: 2 | Q14: -0.726 | S14: 0.885 | X14: -423.64 | Y14: -40.69 | AA14: 86.82 | AE14: 0.1622 | AF14: 1.0669 | AH14: 0.857
A15: B3gas | B15: 1,4-Dichlorobenzene | C15: 1,4-DiCl | D15: ClBz_14 | E15: chlorobenzene | F15: 0.000905247 | H15: -7.0073 | I15: -1.184 | J15: 2.7538 | K15: -5.04 | L15: -37.66 | M15: 4.13 | N15: -9.16 | O15: -41.79 | P15: 2 | Q15: -0.665 | R15: -0.384 | S15: 0.89 | U15: 4.13 | V15: -9.16 | W15: -41.79 | X15: -421.48 | Y15: -32.62 | Z15: 17.13 | AA15: 88.66 | AE15: 0.147 | AF15: 1.0559 | AG15: 0.05043 | AH15: 0.0836
A16: B3SMD | B16: Bromobenzene | C16: MonoBr | D16: BrBz_1 | E16: bromobenzene | F16: 0.002 | G16: 0.00021 | H16: -6.2146 | I16: -0.708 | J16: -1.7437 | K16: -63.58 | L16: -147.23 | M16: -60.42 | N16: -3.16 | O16: -86.81 | P16: 1 | Q16: 1.013 | S16: 1.316 | X16: -214.76 | Y16: -83.65 | AA16: 74.26 | AB16: 26.44 | AC16: 21.24 | AE16: 0.1124 | AF16: 1.0259 | AH16: 1.34
A17: B3SMD | B17: 1,4-Dibromobenzene | C17: 1,4-DiBr | D17: BrBz_14 | E17: bromobenzene | F17: 0.012 | G17: 0.0014 | H17: -4.4228 | I17: -0.992 | J17: -1.6188 | K17: -64.03 | L17: -151.25 | M17: -61.54 | N17: -2.49 | O17: -89.71 | P17: 2 | Q17: 1.234 | S17: 1.447 | X17: -216.7 | Y17: -87.22 | AA17: 74.2 | AB17: 26.01 | AC17: 20.19932 | AE17: 0.1192 | AF17: 1.0325 | AH17: 0.0095
A18: B3SMD | B18: 1,3-Dibromobenzene | C18: 1,3-DiBr | D18: BrBz_13 | E18: bromobenzene | F18: 0.0329 | G18: 0.0031 | H18: -3.4143 | I18: -1.029 | J18: -1.7255 | K18: -65.02 | L18: -153.37 | M18: -61.54 | N18: -3.48 | O18: -91.83 | P18: 2 | Q18: 1.245 | S18: 1.466 | X18: -216.62 | Y18: -88.35 | AA18: 73.29 | AB18: 25.78 | AC18: 19.52932 | AE18: 0.1533 | AF18: 1.0336 | AH18: 0.018
A19: B3SMD | B19: 1,2,4-Tribromobenzene | C19: 1,2,4-TriBr | D19: BrBz_124 | E19: bromobenzene | F19: 0.55 | G19: 0.082 | H19: -0.5978 | I19: -1.426 | J19: -2.0145 | K19: -67.31 | L19: -164.3 | M19: -65.85 | N19: -1.46 | O19: -98.45 | P19: 3 | Q19: 1.521 | S19: 1.649 | X19: -219.79 | Y19: -96.99 | AA19: 70.72 | AB19: 24.8 | AC19: 17.74253 | AE19: 0.3598 | AF19: 1.0392 | AH19: 0.84
A20: B3SMD | B20: 1,3,5-Tribromobenzene | C20: 1,3,5-TriBr | D20: BrBz_135 | E20: bromobenzene | F20: 0.9 | G20: 0.15 | H20: -0.1054 | I20: -1.51 | J20: -1.9519 | K20: -65.46 | L20: -159.14 | M20: -64.5 | N20: -0.97 | O20: -94.64 | P20: 3 | Q20: 1.472 | S20: 1.637 | X20: -217.99 | Y20: -93.68 | AA20: 72.41 | AB20: 25.22 | AC20: 18.54909 | AE20: 0.126 | AF20: 1.0413 | AH20: 0.0219
A21: B3SMD | B21: 1,2,4,5-Tetrabromobenzene | C21: 1,2,4,5-TetrBr | D21: BrBz_1245 | E21: bromobenzene | F21: 2.5 | G21: 0.28 | H21: 0.9163 | I21: -1.758 | J21: -2.0667 | K21: -67.85 | L21: -167.94 | M21: -68.1 | N21: 0.25 | O21: -99.84 | P21: 4 | Q21: 1.815 | S21: 1.874 | X21: -221.89 | Y21: -100.08 | AA21: 70.98 | AB21: 24.58 | AC21: 16.72864 | AE21: 0.2063 | AF21: 1.0505 | AH21: 0.0097
A22: B3SMD | B22: Hexabromobenzene | C22: HexaBr | D22: BrBz_123456 | E22: bromobenzene | F22: 10 | G22: 1.3 | H22: 2.3026 | I22: -2.69 | J22: -2.5353 | K22: -74.57 | L22: -184.25 | M22: -77.05 | N22: 2.49 | O22: -107.2 | P22: 6 | Q22: 2.688 | R22: 3.165 | S22: 2.706 | T22: -0.94 | U22: -77.05 | V22: 2.49 | W22: -107.2 | X22: -227.26 | Y22: -109.69 | Z22: 23.87 | AA22: 64.16 | AB22: 22.42 | AC22: 11.72841 | AE22: 0.1667 | AF22: 1.0616 | AG22: 0.09972 | AH22: 0.0832
A23: B3SMD | B23: BDE-47 | C23: BDE-47 | D23: BDE_24_24 | E23: pbde | F23: 0.078 | G23: 0.018 | H23: -2.551 | I23: -1.271 | J23: -1.932 | K23: -66.26 | L23: -166.45 | M23: -63.25 | N23: -3.02 | O23: -103.2 | P23: 4 | Q23: 1.503 | S23: 1.59 | X23: -219.46 | Y23: -100.19 | AA23: 71.69 | AB23: 23.87 | AC23: 17.06427 | AE23: 0.0946 | AF23: 1.0333 | AH23: 0.0034
A24: B3SMD | B24: BDE-99 | C24: BDE-99 | D24: BDE_245_24 | E24: pbde | F24: 0.45 | G24: 0.068 | H24: -0.7985 | I24: -1.487 | K24: -67.25 | L24: -173.47 | P24: 5 | Q24: 1.64 | S24: 1.706 | X24: -220.63 | Y24: -107.38 | AA24: 71.04 | AB24: 23.56 | AC24: 16.34236 | AE24: 0.1357 | AF24: 1.0364
A25: B3SMD | B25: Hexachlorobenzene | C25: HexaCl | D25: ClBz_123456 | E25: chlorobenzene | F25: 4.7393042 | H25: 1.5559 | I25: -1.904 | J25: -2.8001 | K25: -74.03 | L25: -187.46 | M25: -73.5 | N25: -0.53 | O25: -113.96 | P25: 6 | Q25: 1.88 | R25: 3.026 | S25: 1.94 | T25: -1.094 | U25: -73.5 | V25: -0.53 | W25: -113.96 | X25: -229.4 | Y25: -113.44 | Z25: 82.61 | AA25: 83.47 | AB25: 27.56 | AC25: 16.82841 | AE25: 0.2295 | AF25: 1.0843 | AG25: 0.31336 | AH25: 0.7995
A26: B3SMD | B26: Pentachlorobenzene | C26: PentaCl | D26: ClBz_12345 | E26: chlorobenzene | F26: 0.19793594 | H26: -1.6198 | I26: -1.539 | J26: -2.7135 | K26: -73.41 | L26: -184.82 | M26: -71.62 | N26: -1.79 | O26: -113.2 | P26: 5 | Q26: 1.765 | R26: 2.979 | S26: 1.841 | T26: -1.175 | U26: -71.62 | V26: -1.79 | W26: -113.2 | X26: -227.91 | Y26: -111.41 | Z26: 84.96 | AA26: 83.68 | AB26: 27.81 | AC26: 17.96238 | AE26: 0.2265 | AF26: 1.0726 | AG26: 0.30346 | AH26: 0.8373
A27: B3SMD | B27: 1,2,4,5-Tetrachlorobenzene | C27: 1,2,4,5-TetraCl | D27: ClBz_1245 | E27: chlorobenzene | F27: 0.29523017 | H27: -1.22 | I27: -1.372 | J27: -2.4798 | K27: -70.79 | L27: -172.09 | M27: -67.72 | N27: -3.07 | O27: -104.37 | P27: 4 | Q27: 1.653 | S27: 1.746 | X27: -225.58 | Y27: -101.3 | AA27: 86.94 | AB27: 28.84 | AC27: 19.64864 | AE27: 0.1388 | AF27: 1.0672 | AH27: 0.024
A28: B3SMD | B28: 1,2-Dichlorobenzene | C28: 1,2-DiCl | D28: ClBz_12 | E28: chlorobenzene | F28: 0.042852127 | H28: -3.15 | I28: -0.896 | J28: -3.0937 | K28: -70.02 | L28: -164.42 | M28: -70.07 | N28: 0.04 | O28: -94.35 | P28: 2 | Q28: 1.217 | S28: 1.446 | X28: -222.98 | Y28: -94.4 | AA28: 87.27 | AB28: 29.46 | AC28: 20.97932 | AE28: 0.1334 | AF28: 1.0538 | AH28: 5.221
A29: B3SMD | B29: 1,4-Dichlorobenzene | C29: 1,4-DiCl | D29: ClBz_14 | E29: chlorobenzene | F29: 0.000905247 | H29: -7.0073 | I29: -0.933 | J29: -0.1641 | K29: -67.98 | L29: -155.14 | M29: -38.68 | N29: -29.3 | O29: -116.47 | P29: 2 | Q29: 1.254 | R29: 1.456 | S29: 1.457 | T29: -2.604 | U29: -38.68 | V29: -29.3 | W29: -116.47 | X29: -220.72 | Y29: -87.17 | Z29: 11.31 | AA29: 89.16 | AB29: 29.94 | AC29: 22.32932 | AE29: 0.1166 | AF29: 1.043 | AG29: 0.01484 | AH29: 0.0391
A30: M6gas | B30: Bromobenzene | C30: MonoBr | D30: BrBz_1 | E30: bromobenzene | F30: 0.002 | G30: 0.00021 | H30: -6.2146 | I30: -0.11 | J30: 2.169 | K30: -8.09 | L30: -31.81 | M30: -8.04 | N30: -0.05 | O30: -23.77 | P30: 1 | Q30: -0.76 | S30: 0.898 | X30: -420.73 | Y30: -23.72 | AA30: 77.11 | AE30: 0.0911 | AF30: 1.041 | AH30: 1.0136
A31: M6gas | B31: 1,4-Dibromobenzene | C31: 1,4-DiBr | D31: BrBz_14 | E31: bromobenzene | F31: 0.012 | G31: 0.0014 | H31: -4.4228 | I31: -0.299 | J31: 2.427 | K31: -8.65 | L31: -42.18 | M31: -13.4 | N31: 4.75 | O31: -28.78 | P31: 2 | Q31: -1.072 | S31: 0.791 | X31: -423.09 | Y31: -33.53 | AA31: 76.96 | AE31: 0.3699 | AF31: 1.0456 | AH31: 0.0234
A32: M6gas | B32: 1,3-Dibromobenzene | C32: 1,3-DiBr | D32: BrBz_13 | E32: bromobenzene | F32: 0.0329 | G32: 0.0031 | H32: -3.4143 | I32: -0.273 | J32: 2.2403 | K32: -9.35 | L32: -44.74 | M32: -14.25 | N32: 4.91 | O32: -30.49 | P32: 2 | Q32: -0.638 | S32: 0.942 | X32: -422.85 | Y32: -35.4 | AA32: 76.32 | AE32: 0.1425 | AF32: 1.0467 | AH32: 0.0336
A33: M6gas | B33: 1,2,4-Tribromobenzene | C33: 1,2,4-TriBr | D33: BrBz_124 | E33: bromobenzene | F33: 0.55 | G33: 0.082 | H33: -0.5978 | I33: -0.546 | J33: 2.2202 | K33: -10.52 | L33: -62.05 | M33: -21.29 | N33: 10.77 | O33: -40.76 | P33: 3 | Q33: -0.252 | S33: 1.054 | X33: -425.07 | Y33: -51.53 | AA33: 74.89 | AE33: 0.2598 | AF33: 1.0499 | AH33: 0.6785
A34: M6gas | B34: 1,3,5-Tribromobenzene | C34: 1,3,5-TriBr | D34: BrBz_135 | E34: bromobenzene | F34: 0.9 | G34: 0.15 | H34: -0.1054 | I34: -0.587 | J34: 2.1902 | K34: -10.28 | L34: -56.2 | M34: -20.94 | N34: 10.67 | O34: -35.26 | P34: 3 | Q34: -0.2 | S34: 1.115 | X34: -424.28 | Y34: -45.93 | AA34: 75.65 | AE34: 0.1441 | AF34: 1.0515 | AH34: 0.7074
A35: M6gas | B35: 1,2,4,5-Tetrabromobenzene | C35: 1,2,4,5-TetrBr | D35: BrBz_1245 | E35: bromobenzene | F35: 2.5 | G35: 0.28 | H35: 0.9163 | I35: -0.794 | J35: 2.0588 | K35: -11.14 | L35: -68.02 | M35: -25.56 | N35: 14.43 | O35: -42.46 | P35: 4 | Q35: 0.056 | S35: 1.165 | X35: -426.76 | Y35: -56.88 | AA35: 75.1 | AE35: 0.1556 | AF35: 1.0586 | AH35: 0.0172
A36: M6gas | B36: Hexabromobenzene | C36: HexaBr | D36: BrBz_123456 | E36: bromobenzene | F36: 10 | G36: 1.3 | H36: 2.3026 | I36: -1.601 | J36: 1.3208 | K36: -16.9 | L36: -88.01 | M36: -39.5 | N36: 22.6 | O36: -48.51 | P36: 6 | Q36: 0.876 | R36: 1.451 | S36: 1.534 | U36: -39.5 | V36: 22.6 | W36: -48.51 | X36: -432.03 | Y36: -71.11 | Z36: 27.77 | AA36: 69.97 | AE36: 0.1667 | AF36: 1.0669 | AG36: 0.08734 | AH36: 0.0665
A37: M6gas | B37: BDE-47 | C37: BDE-47 | D37: BDE_24_24 | E37: pbde | F37: 0.078 | G37: 0.018 | H37: -2.551 | I37: -0.723 | J37: 2.0662 | K37: -9.76 | L37: -69.77 | M37: -23.73 | N37: 13.97 | O37: -46.03 | P37: 4 | Q37: 0.042 | S37: 1.098 | X37: -424.42 | Y37: -60 | AA37: 76.05 | AE37: 0.1005 | AF37: 1.043 | AH37: 0.0103
A38: M6gas | B38: BDE-99 | C38: BDE-99 | D38: BDE_245_24 | E38: pbde | F38: 0.45 | G38: 0.068 | H38: -0.7985 | I38: -0.83 | J38: 1.9143 | K38: -10.15 | L38: -79.58 | M38: -24.65 | N38: 14.49 | O38: -54.93 | P38: 5 | Q38: 0.192 | R38: 0.96 | S38: 1.162 | U38: -24.65 | V38: 14.49 | W38: -54.93 | X38: -425.59 | Y38: -70.03 | Z38: 72.74 | AA38: 75.23 | AE38: 0.1321 | AF38: 1.0492 | AG38: 0.3616 | AH38: 0.7017
A39: M6gas | B39: Hexachlorobenzene | C39: HexaCl | D39: ClBz_123456 | E39: chlorobenzene | F39: 4.7393042 | H39: 1.5559 | I39: -0.948 | J39: 2.1696 | K39: -2.78 | L39: -73.47 | M39: -25.14 | N39: 22.36 | O39: -48.33 | P39: 6 | Q39: 0.242 | R39: 0.937 | S39: 1.288 | U39: -25.14 | V39: 22.36 | W39: -48.33 | X39: -419.86 | Y39: -70.69 | Z39: 34.38 | AA39: 91.03 | AE39: 0.2309 | AF39: 1.0898 | AG39: 0.07141 | AH39: 0.0532
A40: M6gas | B40: Pentachlorobenzene | C40: PentaCl | D40: ClBz_12345 | E40: chlorobenzene | F40: 0.19793594 | H40: -1.6198 | I40: -0.85 | J40: 2.1222 | K40: -1.53 | L40: -68.67 | M40: -20.78 | N40: 19.25 | O40: -47.89 | P40: 5 | Q40: 0.081 | R40: 0.762 | S40: 1.212 | U40: -20.78 | V40: 19.25 | W40: -47.89 | X40: -417.97 | Y40: -67.14 | Z40: 65.49 | AA40: 91.2 | AE40: 0.2358 | AF40: 1.08 | AG40: 0.36801 | AH40: 0.5429
...

Sheet B3gas 01 dG rad_red
A1: min_dG_rad_red_kcal | B1: published bromobenzene data | C1: label | D1: y error | G1: min_dG_rad_red_kcal | H1: new chlorobenzene data | I1: label | K1: min_dG_rad_red_kcal | L1: published PBDE data | M1: label | N1: y error | P1: fit x | Q1: fit: published bromobenzene data
A2: -23.94 | B2: -6.2146 | C2: MonoBr | D2: 0.105 | G2: -71.45 | H2: 1.5559 | I2: HexaCl | K2: -59.15 | L2: -2.551 | M2: BDE-47 | N2: 0.2308 | P2: =MIN($A$2:$A$8) | Q2: =$Q$6+$Q$5*P2
A3: -33.64 | B3: -4.4228 | C3: 1,4-DiBr | D3: 0.1167 | G3: -68.1 | H3: -1.6198 | I3: PentaCl | K3: -69.6 | L3: -0.7985 | M3: BDE-99 | N3: 0.1511 | P3: =MAX($A$2:$A$8) | Q3: =$Q$6+$Q$5*P3
A4: -36.39 | B4: -3.4143 | C4: 1,3-DiBr | D4: 0.0942 | G4: -54.95 | H4: -1.22 | I4: 1,2,4,5-TetraCl
A5: -52.41 | B5: -0.5978 | C5: 1,2,4-TriBr | D5: 0.1491 | G5: -40.69 | H5: -3.15 | I5: 1,2-DiCl | P5: slope | Q5: =SLOPE($B$2:$B$8,$A$2:$A$8)
A6: -47.86 | B6: -0.1054 | C6: 1,3,5-TriBr | D6: 0.1667 | G6: -32.62 | H6: -7.0073 | I6: 1,4-DiCl | P6: intercept | Q6: =INTERCEPT($B$2:$B$8,$A$2:$A$8)
A7: -57.37 | B7: 0.9163 | C7: 1,2,4,5-TetrBr | D7: 0.112 | P7: R2 | Q7: =RSQ($B$2:$B$8,$A$2:$A$8)
A8: -72.5 | B8: 2.3026 | C8: HexaBr | D8: 0.13
S17: Natural logarithm of the observed pseudo-first-order rate constants (k_obs, h⁻¹) for electrochemical dehalogenation at −2.0 V vs SHE (uncompensated potential, without iR-drop compensation) [add electrode, cell, electrolyte and pH], plotted against descriptors computed at B3LYP/6-311++G(d), gas phase. Filled gray circles are published bromobenzene data, open circles are new chlorobenzene data and gray squares are published PBDE data. Error bars are ±1 standard error of k_obs propagated to ln k_obs (no standard errors are available for the chlorobenzenes). The dotted line is the least-squares fit to the bromobenzenes (R² = 0.95, n = 7). The other compounds are predicted by that fit. Compounds are labelled by shorthand. Fit line, slope, intercept and R² are Excel formulas (SLOPE, INTERCEPT, RSQ) over the bromobenzene cells beside the chart.

Sheet B3gas 02 dG RA_2e_any
A1: min_dG_RA_2e_any_kcal | B1: published bromobenzene data | C1: label | D1: y error | G1: min_dG_RA_2e_any_kcal | H1: new chlorobenzene data | I1: label | K1: min_dG_RA_2e_any_kcal | L1: published PBDE data | M1: label | N1: y error | P1: fit x | Q1: fit: published bromobenzene data
A2: -24.39 | B2: -6.2146 | C2: MonoBr | D2: 0.105 | G2: -49.07 | H2: 1.5559 | I2: HexaCl | K2: -46.38 | L2: -2.551 | M2: BDE-47 | N2: 0.2308 | P2: =MIN($A$2:$A$8) | Q2: =$Q$6+$Q$5*P2
A3: -28.48 | B3: -4.4228 | C3: 1,4-DiBr | D3: 0.1167 | G3: -50.37 | H3: -1.6198 | I3: PentaCl | K3: -61.35 | L3: -0.7985 | M3: BDE-99 | N3: 0.1511 | P3: =MAX($A$2:$A$8) | Q3: =$Q$6+$Q$5*P3
A4: -30.98 | B4: -3.4143 | C4: 1,3-DiBr | D4: 0.0942 | G4: -41.14 | H4: -1.22 | I4: 1,2,4,5-TetraCl
A5: -42.44 | B5: -0.5978 | C5: 1,2,4-TriBr | D5: 0.1491 | G5: -36.01 | H5: -3.15 | I5: 1,2-DiCl | P5: slope | Q5: =SLOPE($B$2:$B$8,$A$2:$A$8)
A6: -36 | B6: -0.1054 | C6: 1,3,5-TriBr | D6: 0.1667 | G6: -41.79 | H6: -7.0073 | I6: 1,4-DiCl | P6: intercept | Q6: =INTERCEPT($B$2:$B$8,$A$2:$A$8)
A7: -43.71 | B7: 0.9163 | C7: 1,2,4,5-TetrBr | D7: 0.112 | P7: R2 | Q7: =RSQ($B$2:$B$8,$A$2:$A$8)
A8: -50.39 | B8: 2.3026 | C8: HexaBr | D8: 0.13
S17: Natural logarithm of the observed pseudo-first-order rate constants (k_obs, h⁻¹) for electrochemical dehalogenation at −2.0 V vs SHE [add electrode, cell, electrolyte and pH], plotted against descriptors computed at B3LYP/6-311++G(d), gas phase. Filled gray circles are published bromobenzene data, open circles are new chlorobenzene data and gray squares are published PBDE data. Error bars are ±1 standard error of k_obs propagated to ln k_obs (no standard errors are available for the chlorobenzenes). The dotted line is the least-squares fit to the bromobenzenes (R² = 0.92, n = 7). The other compounds are predicted by that fit. Compounds are labelled by shorthand. Fit line, slope, intercept and R² are Excel formulas (SLOPE, INTERCEPT, RSQ) over the bromobenzene cells beside the chart.

Sheet B3gas 03 dG frag_any
A1: min_dG_frag_any_kcal | B1: published bromobenzene data | C1: label | D1: y error | G1: min_dG_frag_any_kcal | H1: new chlorobenzene data | I1: label | K1: min_dG_frag_any_kcal | L1: published PBDE data | M1: label | N1: y error | P1: fit x | Q1: fit: published bromobenzene data
A2: -0.45 | B2: -6.2146 | C2: MonoBr | D2: 0.105 | G2: 22.38 | H2: 1.5559 | I2: HexaCl | K2: 12.77 | L2: -2.551 | M2: BDE-47 | N2: 0.2308 | P2: =MIN($A$2:$A$8) | Q2: =$Q$6+$Q$5*P2
A3: 5.16 | B3: -4.4228 | C3: 1,4-DiBr | D3: 0.1167 | G3: 17.74 | H3: -1.6198 | I3: PentaCl | K3: 7.54 | L3: -0.7985 | M3: BDE-99 | N3: 0.1511 | P3: =MAX($A$2:$A$8) | Q3: =$Q$6+$Q$5*P3
A4: 5.41 | B4: -3.4143 | C4: 1,3-DiBr | D4: 0.0942 | G4: 13.81 | H4: -1.22 | I4: 1,2,4,5-TetraCl
A5: 9.97 | B5: -0.5978 | C5: 1,2,4-TriBr | D5: 0.1491 | G5: 4.67 | H5: -3.15 | I5: 1,2-DiCl | P5: slope | Q5: =SLOPE($B$2:$B$8,$A$2:$A$8)
A6: 11.86 | B6: -0.1054 | C6: 1,3,5-TriBr | D6: 0.1667 | G6: -9.16 | H6: -7.0073 | I6: 1,4-DiCl | P6: intercept | Q6: =INTERCEPT($B$2:$B$8,$A$2:$A$8)
A7: 13.66 | B7: 0.9163 | C7: 1,2,4,5-TetrBr | D7: 0.112 | P7: R2 | Q7: =RSQ($B$2:$B$8,$A$2:$A$8)
A8: 22.11 | B8: 2.3026 | C8: HexaBr | D8: 0.13
S17: Natural logarithm of the observed pseudo-first-order rate constants (k_obs, h⁻¹) for electrochemical dehalogenation at −2.0 V vs SHE [add electrode, cell, electrolyte and pH], plotted against descriptors computed at B3LYP/6-311++G(d), gas phase. Filled gray circles are published bromobenzene data, open circles are new chlorobenzene data and gray squares are published PBDE data. Error bars are ±1 standard error of k_obs propagated to ln k_obs (no standard errors are available for the chlorobenzenes). The dotted line is the least-squares fit to the bromobenzenes (R² = 0.92, n = 7). The other compounds are predicted by that fit. Compounds are labelled by shorthand. Fit line, slope, intercept and R² are Excel formulas (SLOPE, INTERCEPT, RSQ) over the bromobenzene cells beside the chart.

Sheet B3gas 04 LUMO_RA
A1: LUMO_RA_eV | B1: published bromobenzene data | C1: label | D1: y error | G1: LUMO_RA_eV | H1: new chlorobenzene data | I1: label | K1: LUMO_RA_eV | L1: published PBDE data | M1: label | N1: y error | P1: fit x | Q1: fit: published bromobenzene data
A2: 2.0743 | B2: -6.2146 | C2: MonoBr | D2: 0.105 | G2: 0.9818 | H2: 1.5559 | I2: HexaCl | K2: 1.0397 | L2: -2.551 | M2: BDE-47 | N2: 0.2308 | P2: =MIN($A$2:$A$8) | Q2: =$Q$6+$Q$5*P2
A3: 1.96 | B3: -4.4228 | C3: 1,4-DiBr | D3: 0.1167 | G3: 0.9665 | H3: -1.6198 | I3: PentaCl | K3: 0.7611 | L3: -0.7985 | M3: BDE-99 | N3: 0.1511 | P3: =MAX($A$2:$A$8) | Q3: =$Q$6+$Q$5*P3
A4: 1.6376 | B4: -3.4143 | C4: 1,3-DiBr | D4: 0.0942 | G4: 1.4713 | H4: -1.22 | I4: 1,2,4,5-TetraCl
A5: 1.2517 | B5: -0.5978 | C5: 1,2,4-TriBr | D5: 0.1491 | G5: 1.8912 | H5: -3.15 | I5: 1,2-DiCl | P5: slope | Q5: =SLOPE($B$2:$B$8,$A$2:$A$8)
A6: 1.1129 | B6: -0.1054 | C6: 1,3,5-TriBr | D6: 0.1667 | G6: 2.7538 | H6: -7.0073 | I6: 1,4-DiCl | P6: intercept | Q6: =INTERCEPT($B$2:$B$8,$A$2:$A$8)
A7: 0.9924 | B7: 0.9163 | C7: 1,2,4,5-TetrBr | D7: 0.112 | P7: R2 | Q7: =RSQ($B$2:$B$8,$A$2:$A$8)
A8: 0.2231 | B8: 2.3026 | C8: HexaBr | D8: 0.13
S17: Natural logarithm of the observed pseudo-first-order rate constants (k_obs, h⁻¹) for electrochemical dehalogenation at −2.0 V vs SHE [add electrode, cell, electrolyte and pH], plotted against descriptors computed at B3LYP/6-311++G(d), gas phase. Filled gray circles are published bromobenzene data, open circles are new chlorobenzene data and gray squares are published PBDE data. Error bars are ±1 standard error of k_obs propagated to ln k_obs (no standard errors are available for the chlorobenzenes). The dotted line is the least-squares fit to the bromobenzenes (R² = 0.92, n = 7). The other compounds are predicted by that fit. Compounds are labelled by shorthand. Fit line, slope, intercept and R² are Excel formulas (SLOPE, INTERCEPT, RSQ) over the bromobenzene cells beside the chart.

Sheet B3gas 05 dG 2e_carbanion
A1: min_dG_2e_carbanion_kcal | B1: published bromobenzene data | C1: label | D1: y error | G1: min_dG_2e_carbanion_kcal | H1: new chlorobenzene data | I1: label | K1: min_dG_2e_carbanion_kcal | L1: published PBDE data | M1: label | N1: y error | P1: fit x | Q1: fit: published bromobenzene data
A2: -37.3 | B2: -6.2146 | C2: MonoBr | D2: 0.105 | G2: -83.08 | H2: 1.5559 | I2: HexaCl | K2: -74.87 | L2: -2.551 | M2: BDE-47 | N2: 0.2308 | P2: =MIN($A$2:$A$8) | Q2: =$Q$6+$Q$5*P2
A3: -47.41 | B3: -4.4228 | C3: 1,4-DiBr | D3: 0.1167 | G3: -78.49 | H3: -1.6198 | I3: PentaCl | K3: -85.28 | L3: -0.7985 | M3: BDE-99 | N3: 0.1511 | P3: =MAX($A$2:$A$8) | Q3: =$Q$6+$Q$5*P3
A4: -50.97 | B4: -3.4143 | C4: 1,3-DiBr | D4: 0.0942 | G4: -62.59 | H4: -1.22 | I4: 1,2,4,5-TetraCl
A5: -69.17 | B5: -0.5978 | C5: 1,2,4-TriBr | D5: 0.1491 | G5: -47.71 | H5: -3.15 | I5: 1,2-DiCl | P5: slope | Q5: =SLOPE($B$2:$B$8,$A$2:$A$8)
A6: -63.39 | B6: -0.1054 | C6: 1,3,5-TriBr | D6: 0.1667 | G6: -37.66 | H6: -7.0073 | I6: 1,4-DiCl | P6: intercept | Q6: =INTERCEPT($B$2:$B$8,$A$2:$A$8)
A7: -74.6 | B7: 0.9163 | C7: 1,2,4,5-TetrBr | D7: 0.112 | P7: R2 | Q7: =RSQ($B$2:$B$8,$A$2:$A$8)
A8: -97.23 | B8: 2.3026 | C8: HexaBr | D8: 0.13
S17: Natural logarithm of the observed pseudo-first-order rate constants (k_obs, h⁻¹) for electrochemical dehalogenation at −2.0 V vs SHE [add electrode, cell, electrolyte and pH], plotted against descriptors computed at B3LYP/6-311++G(d), gas phase. Filled gray circles are published bromobenzene data, open circles are new chlorobenzene data and gray squares are published PBDE data. Error bars are ±1 standard error of k_obs propagated to ln k_obs (no standard errors are available for the chlorobenzenes). The dotted line is the least-squares fit to the bromobenzenes (R² = 0.91, n = 7). The other compounds are predicted by that fit. Compounds are labelled by shorthand. Fit line, slope, intercept and R² are Excel formulas (SLOPE, INTERCEPT, RSQ) over the bromobenzene cells beside the chart.

Sheet B3gas 06 n_X
A1: n_X | B1: published bromobenzene data | C1: label | D1: y error | G1: n_X | H1: new chlorobenzene data | I1: label | K1: n_X | L1: published PBDE data | M1: label | N1: y error | P1: fit x | Q1: fit: published bromobenzene data
A2: 1 | B2: -6.2146 | C2: MonoBr | D2: 0.105 | G2: 6 | H2: 1.5559 | I2: HexaCl | K2: 4 | L2: -2.551 | M2: BDE-47 | N2: 0.2308 | P2: =MIN($A$2:$A$8) | Q2: =$Q$6+$Q$5*P2
A3: 2 | B3: -4.4228 | C3: 1,4-DiBr | D3: 0.1167 | G3: 5 | H3: -1.6198 | I3: PentaCl | K3: 5 | L3: -0.7985 | M3: BDE-99 | N3: 0.1511 | P3: =MAX($A$2:$A$8) | Q3: =$Q$6+$Q$5*P3
A4: 2 | B4: -3.4143 | C4: 1,3-DiBr | D4: 0.0942 | G4: 4 | H4: -1.22 | I4: 1,2,4,5-TetraCl
A5: 3 | B5: -0.5978 | C5: 1,2,4-TriBr | D5: 0.1491 | G5: 2 | H5: -3.15 | I5: 1,2-DiCl | P5: slope | Q5: =SLOPE($B$2:$B$8,$A$2:$A$8)
A6: 3 | B6: -0.1054 | C6: 1,3,5-TriBr | D6: 0.1667 | G6: 2 | H6: -7.0073 | I6: 1,4-DiCl | P6: intercept | Q6: =INTERCEPT($B$2:$B$8,$A$2:$A$8)
A7: 4 | B7: 0.9163 | C7: 1,2,4,5-TetrBr | D7: 0.112 | P7: R2 | Q7: =RSQ($B$2:$B$8,$A$2:$A$8)
A8: 6 | B8: 2.3026 | C8: HexaBr | D8: 0.13
S17: Natural logarithm of the observed pseudo-first-order rate constants (k_obs, h⁻¹) for electrochemical dehalogenation at −2.0 V vs SHE [add electrode, cell, electrolyte and pH], plotted against descriptors computed at B3LYP/6-311++G(d), gas phase. Filled gray circles are published bromobenzene data, open circles are new chlorobenzene data and gray squares are published PBDE data. Error bars are ±1 standard error of k_obs propagated to ln k_obs (no standard errors are available for the chlorobenzenes). The dotted line is the least-squares fit to the bromobenzenes (R² = 0.86, n = 7). The other compounds are predicted by that fit. Compounds are labelled by shorthand. Fit line, slope, intercept and R² are Excel formulas (SLOPE, INTERCEPT, RSQ) over the bromobenzene cells beside the chart.

Sheet B3gas 07 dG ET_any
A1: dG_ET_any_kcal | B1: published bromobenzene data | C1: label | D1: y error | G1: dG_ET_any_kcal | H1: new chlorobenzene data | I1: label | K1: dG_ET_any_kcal | L1: published PBDE data | M1: label | N1: y error | P1: fit x | Q1: fit: published bromobenzene data
A2: -12.91 | B2: -6.2146 | C2: MonoBr | D2: 0.105 | G2: -34.01 | H2: 1.5559 | I2: HexaCl | K2: -28.49 | L2: -2.551 | M2: BDE-47 | N2: 0.2308 | P2: =MIN($A$2:$A$8) | Q2: =$Q$6+$Q$5*P2
A3: -18.93 | B3: -4.4228 | C3: 1,4-DiBr | D3: 0.1167 | G3: -28.12 | H3: -1.6198 | I3: PentaCl | K3: -23.93 | L3: -0.7985 | M3: BDE-99 | N3: 0.1511 | P3: =MAX($A$2:$A$8) | Q3: =$Q$6+$Q$5*P3
A4: -19.99 | B4: -3.4143 | C4: 1,3-DiBr | D4: 0.0942 | G4: -21.44 | H4: -1.22 | I4: 1,2,4,5-TetraCl
A5: -26.74 | B5: -0.5978 | C5: 1,2,4-TriBr | D5: 0.1491 | G5: -11.69 | H5: -3.15 | I5: 1,2-DiCl | P5: slope | Q5: =SLOPE($B$2:$B$8,$A$2:$A$8)
A6: -27.39 | B6: -0.1054 | C6: 1,3,5-TriBr | D6: 0.1667 | G6: 4.13 | H6: -7.0073 | I6: 1,4-DiCl | P6: intercept | Q6: =INTERCEPT($B$2:$B$8,$A$2:$A$8)
A7: -30.89 | B7: 0.9163 | C7: 1,2,4,5-TetrBr | D7: 0.112 | P7: R2 | Q7: =RSQ($B$2:$B$8,$A$2:$A$8)
A8: -46.83 | B8: 2.3026 | C8: HexaBr | D8: 0.13
S17: Natural logarithm of the observed pseudo-first-order rate constants (k_obs, h⁻¹) for electrochemical dehalogenation at −2.0 V vs SHE [add electrode, cell, electrolyte and pH], plotted against descriptors computed at B3LYP/6-311++G(d), gas phase. Filled gray circles are published bromobenzene data, open circles are new chlorobenzene data and gray squares are published PBDE data. Error bars are ±1 standard error of k_obs propagated to ln k_obs (no standard errors are available for the chlorobenzenes). The dotted line is the least-squares fit to the bromobenzenes (R² = 0.86, n = 7). The other compounds are predicted by that fit. Compounds are labelled by shorthand. Fit line, slope, intercept and R² are Excel formulas (SLOPE, INTERCEPT, RSQ) over the bromobenzene cells beside the chart.

Sheet B3gas 08 wiberg_CX_parent
A1: min_wiberg_CX_parent | B1: published bromobenzene data | C1: label | D1: y error | G1: min_wiberg_CX_parent | H1: new chlorobenzene data | I1: label | K1: min_wiberg_CX_parent | L1: published PBDE data | M1: label | N1: y error | P1: fit x | Q1: fit: published bromobenzene data
A2: 1.0359 | B2: -6.2146 | C2: MonoBr | D2: 0.105 | G2: 1.0891 | H2: 1.5559 | I2: HexaCl | K2: 1.0412 | L2: -2.551 | M2: BDE-47 | N2: 0.2308 | P2: =MIN($A$2:$A$8) | Q2: =$Q$6+$Q$5*P2
A3: 1.0408 | B3: -4.4228 | C3: 1,4-DiBr | D3: 0.1167 | G3: 1.0783 | H3: -1.6198 | I3: PentaCl | K3: 1.0454 | L3: -0.7985 | M3: BDE-99 | N3: 0.1511 | P3: =MAX($A$2:$A$8) | Q3: =$Q$6+$Q$5*P3
A4: 1.0417 | B4: -3.4143 | C4: 1,3-DiBr | D4: 0.0942 | G4: 1.0754 | H4: -1.22 | I4: 1,2,4,5-TetraCl
A5: 1.0452 | B5: -0.5978 | C5: 1,2,4-TriBr | D5: 0.1491 | G5: 1.0669 | H5: -3.15 | I5: 1,2-DiCl | P5: slope | Q5: =SLOPE($B$2:$B$8,$A$2:$A$8)
A6: 1.0465 | B6: -0.1054 | C6: 1,3,5-TriBr | D6: 0.1667 | G6: 1.0559 | H6: -7.0073 | I6: 1,4-DiCl | P6: intercept | Q6: =INTERCEPT($B$2:$B$8,$A$2:$A$8)
A7: 1.0544 | B7: 0.9163 | C7: 1,2,4,5-TetrBr | D7: 0.112 | P7: R2 | Q7: =RSQ($B$2:$B$8,$A$2:$A$8)
A8: 1.0634 | B8: 2.3026 | C8: HexaBr | D8: 0.13
S17: Natural logarithm of the observed pseudo-first-order rate constants (k_obs, h⁻¹) for electrochemical dehalogenation at −2.0 V vs SHE [add electrode, cell, electrolyte and pH], plotted against descriptors computed at B3LYP/6-311++G(d), gas phase. Filled gray circles are published bromobenzene data, open circles are new chlorobenzene data and gray squares are published PBDE data. Error bars are ±1 standard error of k_obs propagated to ln k_obs (no standard errors are available for the chlorobenzenes). The dotted line is the least-squares fit to the bromobenzenes (R² = 0.85, n = 7). The other compounds are predicted by that fit. Compounds are labelled by shorthand. Fit line, slope, intercept and R² are Excel formulas (SLOPE, INTERCEPT, RSQ) over the bromobenzene cells beside the chart.

Sheet B3gas 09 LUMO
A1: LUMO_eV | B1: published bromobenzene data | C1: label | D1: y error | G1: LUMO_eV | H1: new chlorobenzene data | I1: label | K1: LUMO_eV | L1: published PBDE data | M1: label | N1: y error | P1: fit x | Q1: fit: published bromobenzene data
A2: -0.84 | B2: -6.2146 | C2: MonoBr | D2: 0.105 | G2: -1.995 | H2: 1.5559 | I2: HexaCl | K2: -1.575 | L2: -2.551 | M2: BDE-47 | N2: 0.2308 | P2: =MIN($A$2:$A$8) | Q2: =$Q$6+$Q$5*P2
A3: -1.201 | B3: -4.4228 | C3: 1,4-DiBr | D3: 0.1167 | G3: -1.785 | H3: -1.6198 | I3: PentaCl | K3: -1.69 | L3: -0.7985 | M3: BDE-99 | N3: 0.1511 | P3: =MAX($A$2:$A$8) | Q3: =$Q$6+$Q$5*P3
A4: -1.19 | B4: -3.4143 | C4: 1,3-DiBr | D4: 0.0942 | G4: -1.67 | H4: -1.22 | I4: 1,2,4,5-TetraCl
A5: -1.525 | B5: -0.5978 | C5: 1,2,4-TriBr | D5: 0.1491 | G5: -1.1 | H5: -3.15 | I5: 1,2-DiCl | P5: slope | Q5: =SLOPE($B$2:$B$8,$A$2:$A$8)
A6: -1.638 | B6: -0.1054 | C6: 1,3,5-TriBr | D6: 0.1667 | G6: -1.184 | H6: -7.0073 | I6: 1,4-DiCl | P6: intercept | Q6: =INTERCEPT($B$2:$B$8,$A$2:$A$8)
A7: -1.863 | B7: 0.9163 | C7: 1,2,4,5-TetrBr | D7: 0.112 | P7: R2 | Q7: =RSQ($B$2:$B$8,$A$2:$A$8)
A8: -2.723 | B8: 2.3026 | C8: HexaBr | D8: 0.13
S17: Natural logarithm of the observed pseudo-first-order rate constants (k_obs, h⁻¹) for electrochemical dehalogenation at −2.0 V vs SHE [add electrode, cell, electrolyte and pH], plotted against descriptors computed at B3LYP/6-311++G(d), gas phase. Filled gray circles are published bromobenzene data, open circles are new chlorobenzene data and gray squares are published PBDE data. Error bars are ±1 standard error of k_obs propagated to ln k_obs (no standard errors are available for the chlorobenzenes). The dotted line is the least-squares fit to the bromobenzenes (R² = 0.84, n = 7). The other compounds are predicted by that fit. Compounds are labelled by shorthand. Fit line, slope, intercept and R² are Excel formulas (SLOPE, INTERCEPT, RSQ) over the bromobenzene cells beside the chart.

Sheet B3gas 10 VEA
A1: VEA_eV | B1: published bromobenzene data | C1: label | D1: y error | G1: VEA_eV | H1: new chlorobenzene data | I1: label | K1: VEA_eV | L1: published PBDE data | M1: label | N1: y error | P1: fit x | Q1: fit: published bromobenzene data
A2: -0.449 | B2: -6.2146 | C2: MonoBr | D2: 0.105 | G2: 0.256 | H2: 1.5559 | I2: HexaCl | K2: 0.235 | L2: -2.551 | M2: BDE-47 | N2: 0.2308 | P2: =MIN($A$2:$A$8) | Q2: =$Q$6+$Q$5*P2
A3: -0.671 | B3: -4.4228 | C3: 1,4-DiBr | D3: 0.1167 | G3: 0.106 | H3: -1.6198 | I3: PentaCl | K3: 0.41 | L3: -0.7985 | M3: BDE-99 | N3: 0.1511 | P3: =MAX($A$2:$A$8) | Q3: =$Q$6+$Q$5*P3
A4: -0.222 | B4: -3.4143 | C4: 1,3-DiBr | D4: 0.0942 | G4: -0.052 | H4: -1.22 | I4: 1,2,4,5-TetraCl
A5: 0.063 | B5: -0.5978 | C5: 1,2,4-TriBr | D5: 0.1491 | G5: -0.726 | H5: -3.15 | I5: 1,2-DiCl | P5: slope | Q5: =SLOPE($B$2:$B$8,$A$2:$A$8)
A6: 0.164 | B6: -0.1054 | C6: 1,3,5-TriBr | D6: 0.1667 | G6: -0.665 | H6: -7.0073 | I6: 1,4-DiCl | P6: intercept | Q6: =INTERCEPT($B$2:$B$8,$A$2:$A$8)
A7: 0.417 | B7: 0.9163 | C7: 1,2,4,5-TetrBr | D7: 0.112 | P7: R2 | Q7: =RSQ($B$2:$B$8,$A$2:$A$8)
A8: 1.313 | B8: 2.3026 | C8: HexaBr | D8: 0.13
S17: Natural logarithm of the observed pseudo-first-order rate constants (k_obs, h⁻¹) for electrochemical dehalogenation at −2.0 V vs SHE [add electrode, cell, electrolyte and pH], plotted against descriptors computed at B3LYP/6-311++G(d), gas phase. Filled gray circles are published bromobenzene data, open circles are new chlorobenzene data and gray squares are published PBDE data. Error bars are ±1 standard error of k_obs propagated to ln k_obs (no standard errors are available for the chlorobenzenes). The dotted line is the least-squares fit to the bromobenzenes (R² = 0.80, n = 7). The other compounds are predicted by that fit. Compounds are labelled by shorthand. Fit line, slope, intercept and R² are Excel formulas (SLOPE, INTERCEPT, RSQ) over the bromobenzene cells beside the chart.

Sheet B3gas 11 dG 2e_HDH
A1: min_dG_2e_HDH_kcal | B1: published bromobenzene data | C1: label | D1: y error | G1: min_dG_2e_HDH_kcal | H1: new chlorobenzene data | I1: label | K1: min_dG_2e_HDH_kcal | L1: published PBDE data | M1: label | N1: y error | P1: fit x | Q1: fit: published bromobenzene data
A2: -427.77 | B2: -6.2146 | C2: MonoBr | D2: 0.105 | G2: -429.78 | H2: 1.5559 | I2: HexaCl | K2: -432.05 | L2: -2.551 | M2: BDE-47 | N2: 0.2308 | P2: =MIN($A$2:$A$8) | Q2: =$Q$6+$Q$5*P2
A3: -430.06 | B3: -4.4228 | C3: 1,4-DiBr | D3: 0.1167 | G3: -427.83 | H3: -1.6198 | I3: PentaCl | K3: -433.68 | L3: -0.7985 | M3: BDE-99 | N3: 0.1511 | P3: =MAX($A$2:$A$8) | Q3: =$Q$6+$Q$5*P3
A4: -429.7 | B4: -3.4143 | C4: 1,3-DiBr | D4: 0.0942 | G4: -425.53 | H4: -1.22 | I4: 1,2,4,5-TetraCl
A5: -432.76 | B5: -0.5978 | C5: 1,2,4-TriBr | D5: 0.1491 | G5: -423.64 | H5: -3.15 | I5: 1,2-DiCl | P5: slope | Q5: =SLOPE($B$2:$B$8,$A$2:$A$8)
A6: -431.09 | B6: -0.1054 | C6: 1,3,5-TriBr | D6: 0.1667 | G6: -421.48 | H6: -7.0073 | I6: 1,4-DiCl | P6: intercept | Q6: =INTERCEPT($B$2:$B$8,$A$2:$A$8)
A7: -434.37 | B7: 0.9163 | C7: 1,2,4,5-TetrBr | D7: 0.112 | P7: R2 | Q7: =RSQ($B$2:$B$8,$A$2:$A$8)
A8: -440.64 | B8: 2.3026 | C8: HexaBr | D8: 0.13
S17: Natural logarithm of the observed pseudo-first-order rate constants (k_obs, h⁻¹) for electrochemical dehalogenation at −2.0 V vs SHE [add electrode, cell, electrolyte and pH], plotted against descriptors computed at B3LYP/6-311++G(d), gas phase. Filled gray circles are published bromobenzene data, open circles are new chlorobenzene data and gray squares are published PBDE data. Error bars are ±1 standard error of k_obs propagated to ln k_obs (no standard errors are available for the chlorobenzenes). The dotted line is the least-squares fit to the bromobenzenes (R² = 0.76, n = 7). The other compounds are predicted by that fit. Compounds are labelled by shorthand. Fit line, slope, intercept and R² are Excel formulas (SLOPE, INTERCEPT, RSQ) over the bromobenzene cells beside the chart.

Sheet B3gas 12 omega_dSCF
A1: omega_dSCF_eV | B1: published bromobenzene data | C1: label | D1: y error | G1: omega_dSCF_eV | H1: new chlorobenzene data | I1: label | K1: omega_dSCF_eV | L1: published PBDE data | M1: label | N1: y error | P1: fit x | Q1: fit: published bromobenzene data
A2: 0.957 | B2: -6.2146 | C2: MonoBr | D2: 0.105 | G2: 1.244 | H2: 1.5559 | I2: HexaCl | K2: 1.099 | L2: -2.551 | M2: BDE-47 | N2: 0.2308 | P2: =MIN($A$2:$A$8) | Q2: =$Q$6+$Q$5*P2
A3: 0.863 | B3: -4.4228 | C3: 1,4-DiBr | D3: 0.1167 | G3: 1.174 | H3: -1.6198 | I3: PentaCl | K3: 1.192 | L3: -0.7985 | M3: BDE-99 | N3: 0.1511 | P3: =MAX($A$2:$A$8) | Q3: =$Q$6+$Q$5*P3
A4: 1.032 | B4: -3.4143 | C4: 1,3-DiBr | D4: 0.0942 | G4: 1.103 | H4: -1.22 | I4: 1,2,4,5-TetraCl
A5: 1.118 | B5: -0.5978 | C5: 1,2,4-TriBr | D5: 0.1491 | G5: 0.885 | H5: -3.15 | I5: 1,2-DiCl | P5: slope | Q5: =SLOPE($B$2:$B$8,$A$2:$A$8)
A6: 1.199 | B6: -0.1054 | C6: 1,3,5-TriBr | D6: 0.1667 | G6: 0.89 | H6: -7.0073 | I6: 1,4-DiCl | P6: intercept | Q6: =INTERCEPT($B$2:$B$8,$A$2:$A$8)
A7: 1.257 | B7: 0.9163 | C7: 1,2,4,5-TetrBr | D7: 0.112 | P7: R2 | Q7: =RSQ($B$2:$B$8,$A$2:$A$8)
A8: 1.709 | B8: 2.3026 | C8: HexaBr | D8: 0.13
S17: Natural logarithm of the observed pseudo-first-order rate constants (k_obs, h⁻¹) for electrochemical dehalogenation at −2.0 V vs SHE [add electrode, cell, electrolyte and pH], plotted against descriptors computed at B3LYP/6-311++G(d), gas phase. Filled gray circles are published bromobenzene data, open circles are new chlorobenzene data and gray squares are published PBDE data. Error bars are ±1 standard error of k_obs propagated to ln k_obs (no standard errors are available for the chlorobenzenes). The dotted line is the least-squares fit to the bromobenzenes (R² = 0.74, n = 7). The other compounds are predicted by that fit. Compounds are labelled by shorthand. Fit line, slope, intercept and R² are Excel formulas (SLOPE, INTERCEPT, RSQ) over the bromobenzene cells beside the chart.

Sheet B3gas 13 dG 1e
A1: min_dG_1e_kcal | B1: published bromobenzene data | C1: label | D1: y error | G1: min_dG_1e_kcal | H1: new chlorobenzene data | I1: label | K1: min_dG_1e_kcal | L1: published PBDE data | M1: label | N1: y error | P1: fit x | Q1: fit: published bromobenzene data
